Workbook
Name ParamList: Lists!$A$5:$A$61
Name GWParam: Lists!$C$5:$C$96
Name GWStart: Lists!$D$5
Name CauseKey: Lists!$H$5:$H$833
Name CauseStart: Lists!$I$5
Name PSICategories: Lists!$N$5:$N$11
Name IPLList: Lists!$P$5:$P$6
Name NodeList: Nodes!$C$5:$C$34
Name RiskGrid: 'Risk Matrix'!$C$5:$G$9
Name BandMed: 'Risk Matrix'!$C$13
Name BandHigh: 'Risk Matrix'!$C$14
Name BandVH: 'Risk Matrix'!$C$15
Name SevList: 'Risk Matrix'!$B$19:$B$23
Name LikList: 'Risk Matrix'!$B$26:$B$30

Sheet Cover
A1: HAZOP STUDY WORKBOOK
A2: Hazard and Operability Study – chemical, steel & metals processes
A4: Legend: | B4: Yellow = enter / select data | C4: Grey = formula (do not overwrite) | D4: Blue = returned from another sheet
A6: STUDY DETAILS
A7: Study title | B7: PHA / HAZOP – Natural gas distribution network (worked example)
A8: Company / site | B8: Hadeed – integrated DRI-EAF steel works (illustrative example)
A9: Plant / unit / area | B9: Utilities – natural gas receiving, pressure reduction and plant distribution
A10: Project / MOC reference | B10: PHA revalidation – plant natural gas network
A11: Study type | B11: HAZOP – revalidation
A12: Document number | B12: HZ-EX-GN-001
A13: Revision | B13: A
A14: Study start date | B14: 2026-10-12
A15: Study end date | B15: 2026-10-14
A16: Venue / platform | B16: Utilities training room
A17: Scope of study | B17: Natural gas from the supplier's custody-transfer battery limit through the gas receiving & metering station (GRMS), gas heaters and pressure reduction station PRS-1, the 7 barg MP ring main, the district stations and fuel trains of the DRI plant (DS-2), melt shop (DS-3) and rolling-mill reheat furnace (DS-4 / fuel train), the purge / vent / blowdown facilities, and the gas detection & ESD system protecting the network.
A18: Exclusions | B18: Supplier pipeline upstream of ESDV-1001; burner internals and combustion inside the DRI reformer (covered by the DRI plant HAZOP); oxygen plant and O2 distribution (except the NG/O2 interface at oxy-fuel burners); plant N2 generation.
... A24: Guideword set | B24: HAZOP Guidewords – Chemical, Steel & Metals (see 'Lists' sheet)
A25: Number of nodes | B25: =COUNTA(Nodes!B5:B34)
A27: STUDY TEAM
A28: Name | B28: Company | C28: Discipline / role | D28: Sessions / days attended | E28: Signature
A29: A. Facilitator | B29: Istec | C29: Facilitator | D29: Days 1–3
A30: B. Scribe | B30: Istec | C30: Scribe | D30: Days 1–3
A31: C. Gas Network | B31: Utilities | C31: Process engineer | D31: Days 1–3
A32: D. Operator | B32: Utilities | C32: Operations representative | D32: Days 1–3
A33: E. Instrument | B33: Maintenance | C33: Instrument / control engineer | D33: Days 1–3
A34: F. Mechanical | B34: Maintenance | C34: Mechanical engineer | D34: Days 1–2
A35: G. Safety | B35: HSE | C35: HSE / process safety | D35: Days 1–3
A36: H. Furnace | B36: Rolling mill | C36: Operations representative | D36: Day 3
A37: I. DRI | B37: DRI plant | C37: Process engineer | D37: Day 2
A42: APPROVAL
B43: Name | C43: Position | D43: Signature | E43: Date
A44: Prepared by
A45: Reviewed by
A46: Approved by
A48: WORKBOOK CONTENTS
A49: Cover | B49: Study details, team, approval
A50: PSI | B50: Process safety information register – drawings, procedures, data used in the study
A51: Nodes | B51: Node list: name, drawings, battery limits, functional description, design and operating parameters
A52: Lists | B52: Drop-down sources: parameters, guidewords, potential causes, PSI categories (editable)
A53: Risk Matrix | B53: 5 x 5 severity x likelihood matrix (scores 1–25), descriptors and risk bands (editable)
...

Sheet PSI
A1: PROCESS SAFETY INFORMATION REGISTER
A2: List every drawing, procedure and data source used by the team. Pre-filled with a typical checklist – delete or add rows as required.
A4: Ref | B4: Category | C4: Document number | D4: Title / description | E4: Revision | F4: Date | G4: Owner / custodian | H4: Status | I4: Applicable nodes | J4: Comments
A5: PSI-01 | B5: Drawings | C5: P&ID-GN-1001 | D5: Gas receiving & metering station (GRMS) P&ID | E5: A | G5: Utilities | H5: Available | I5: N01
A6: PSI-02 | B6: Drawings | C6: P&ID-GN-1101 | D6: Gas heaters and pressure reduction station PRS-1 P&ID | E6: A | G6: Utilities | H6: Available | I6: N02
A7: PSI-03 | B7: Drawings | C7: P&ID-GN-1201/1202 | D7: MP ring main and pipe-rack routing | E7: A | G7: Utilities | H7: Available | I7: N03
A8: PSI-04 | B8: Drawings | C8: P&ID-GN-2001 | D8: DRI plant district station DS-2 | E8: A | G8: Utilities | H8: Available | I8: N04
A9: PSI-05 | B9: Drawings | C9: P&ID-GN-3001 | D9: Melt shop district station DS-3, oxy-fuel burners and ladle preheaters | E9: A | G9: Utilities | H9: Available | I9: N05
A10: PSI-06 | B10: Drawings | C10: P&ID-GN-4001 | D10: Rolling-mill reheat furnace fuel gas train and BMS | E10: A | G10: Utilities | H10: Available | I10: N06
A11: PSI-07 | B11: Drawings | C11: P&ID-GN-1301 | D11: Vent stack, blowdown and N2 purge connections | E11: A | G11: Utilities | H11: Available | I11: N07
A12: PSI-08 | B12: Drawings | C12: C&E-GN-1000 | D12: ESD / F&G cause-and-effect charts | E12: A | G12: Utilities | H12: Available | I12: N01, N02, N08
A13: PSI-09 | B13: Drawings | C13: HAC-GN-001 | D13: Hazardous area classification – gas network | E13: A | G13: Utilities | H13: Available | I13: N01, N02, N03, N07
A14: PSI-10 | B14: Process technology | C14: DB-GN-001 | D14: Gas network design basis (pressures, set points, MDMT) | E14: A | G14: Utilities | H14: Available | I14: N01, N02, N03
A15: PSI-11 | B15: Equipment | C15: RS-GN-001 | D15: Relief and overpressure protection study | E15: A | G15: Utilities | H15: Available | I15: N01, N02, N07
A16: PSI-12 | B16: Equipment | C16: SRS-GN-001 | D16: Safety requirements specification – gas ESD and furnace BMS | E16: A | G16: Utilities | H16: Available | I16: N06, N08
... A22: PSI-18 | B22: Previous studies | C22: INC-GN-LOG | D22: Gas incident / near-miss log (last 5 years) | E22: A | G22: Utilities | H22: Available | I22: N03, N05, N06
A23: PSI-19
A24: PSI-20
A25: PSI-21
A26: PSI-22
A27: PSI-23
A28: PSI-24
A29: PSI-25
A30: PSI-26
A31: PSI-27
A32: PSI-28
A33: PSI-29
A34: PSI-30
... A54: PSI-50

Sheet Nodes
A1: NODE LIST
A2: One row per node. Node title (column C) feeds the drop-down at the top of each node worksheet.
A4: Node No. | B4: Node name | C4: Node title (auto) | D4: P&IDs / drawings | E4: Battery limits (from – to) | F4: Functional description / design intent | G4: Design parameters | H4: Operating parameters | I4: Comments
A5: N01 | B5: Gas receiving & metering station (GRMS) | C5: =IF(B5="","",A5&" – "&B5) | D5: P&ID-GN-1001 | E5: From the supplier battery-limit insulating joint IJ-1001 through inlet ESD valve ESDV-1001, pig receiver PR-1001, filter-separators F-1002A/B and ultrasonic meter runs FT-1003A/B to the inlet of the gas heaters | F5: Receive natural gas from the supplier's pipeline, remove liquids and solids and meter it for custody transfer | G5: Design 50 barg / -10 to 60 °C (= pipeline MAOP); 2 x 100 % filter-separators; 2 x 100 % meter runs | H5: 35–42 barg; 20–35 °C; up to 120 000 Sm3/h | I5: Materials: Natural gas (methane > 90 %, extremely flammable, asphyxiant); traces of H2S, condensate, black powder
A6: N02 | B6: Gas heaters H-1101A/B and pressure reduction station PRS-1 | C6: =IF(B6="","",A6&" – "&B6) | D6: P&ID-GN-1101 | E6: From the heater inlet through water-bath heaters H-1101A/B and regulator runs A/B (slam-shut SSV-1102, monitor PCV-1103, active PCV-1104) to outlet ESD valve ESDV-1107, incl. token relief PSV-1105 | F6: Pre-heat the gas to offset Joule–Thomson cooling (~0.5 °C per bar) and reduce it from 35–42 barg to 7 barg without exceeding the MP design pressure | G6: Inlet 50 barg; outlet piping 10 barg design; set points: active 7.0, monitor 7.5, SSV OPSO 8.5, PSV-1105 9.0 barg; outlet temperature ≥ 5 °C | H6: Outlet 6.8–7.2 barg; heater outlet 30–40 °C upstream of the regulators; run A duty / run B standby (set 0.3 bar lower) | I6: Materials: Natural gas; hot water / glycol bath; heater flue gases
A7: N03 | B7: MP ring main (7 barg) and pipe racks | C7: =IF(B7="","",A7&" – "&B7) | D7: P&ID-GN-1201/1202 | E7: From ESDV-1107 around the plant ring main (24") with sectionalising valves XV-1201…1204 to the inlet isolation of each district station (DS-2, DS-3, DS-4); buried road crossings with cathodic protection CP-1200 | F7: Distribute 7 barg gas to all plant users with sectional isolation and without loss of containment | G7: Design 10 barg; API 5L carbon steel; buried sections coated + impressed-current CP | H7: 6.8–7.2 barg; ambient temperature | I7: Materials: Natural gas
A8: N04 | B8: DRI plant gas supply – district station DS-2 | C8: =IF(B8="","",A8&" – "&B8) | D8: P&ID-GN-2001 | E8: From the DS-2 inlet ESDV-2001 via regulators PCV-2002A/B to the reformer fuel gas control valve FCV-2004 and the process-gas NG make-up point (XV-2008) | F8: Supply natural gas to the DRI reformer burners (fuel) and as make-up to the reducing-gas circuit at controlled pressure and flow | G8: Design 10 barg (full MP pressure); outlet 4.5 barg | H8: 4.0–4.5 barg; flow on reformer firing demand | I8: Materials: Natural gas; reducing / process gas (H2, CO – toxic, flammable) at the make-up point
A9: N05 | B9: Melt shop gas supply – DS-3, EAF oxy-fuel burners and ladle preheaters | C9: =IF(B9="","",A9&" – "&B9) | D9: P&ID-GN-3001 | E9: From DS-3 inlet ESDV-3001 via PCV-3002A, slam-shut SSV-3003 and PSV-3004 to the EAF oxy-fuel burner skids (XV-3011, NRV-3010) and ladle preheaters LPH-3020 | F9: Supply natural gas to the EAF oxy-fuel burners and ladle / tundish preheaters at controlled pressure | G9: Design 10 barg; outlet 2.0 barg; O2 supply to burners 10 barg | H9: 1.8–2.0 barg; intermittent firing | I9: Materials: Natural gas; oxygen (oxidiser); molten metal / slag nearby
A10: N06 | B10: Rolling-mill reheat furnace fuel gas train and burner management | C10: =IF(B10="","",A10&" – "&B10) | D10: P&ID-GN-4001 | E10: From DS-4 regulator PCV-4001 through safety shut-off valves XV-4002A/B (with vent XV-4003 and valve proving VPS-4004) to the zone burners B-4020, incl. BMS-4000, flame scanners BS-4010 and combustion air fan FN-4007 | F10: Deliver fuel gas to the reheat furnace burners only when safe to fire (purged, air proven, flame proven) and shut it off on any unsafe condition | G10: Design 10 barg upstream / 2 barg downstream of PCV-4001; SSOV closing time < 1 s | H10: 0.3–1.5 barg at the burners; furnace 900–1250 °C; light-off from cold after outages | I10: Materials: Natural gas; combustion air; flue gas (CO)
A11: N07 | B11: Purge, vent, blowdown and maintenance isolation | C11: =IF(B11="","",A11&" – "&B11) | D11: P&ID-GN-1301 | E11: Vent stack VS-1301 and blowdown valve BDV-1302 at the PRS, spectacle blinds SB-1303 and N2 purge connections N2-1304 at GRMS, PRS and district stations | F11: Allow equipment to be depressurised, purged, isolated and returned to service without creating flammable mixtures, releases or asphyxiation hazards | G11: Vent stack 3 m above the highest platform within 15 m; N2 purge supply 8 barg | H11: Used during maintenance, pigging and gas-in / gas-out | I11: Materials: Natural gas; nitrogen (asphyxiant); air
A12: N08 | B12: Gas detection, F&G and ESD system | C12: =IF(B12="","",A12&" – "&B12) | D12: C&E-GN-1000 | E12: Gas detectors GD-1110A/B/C (PRS shelter, 2oo3), GRMS detectors, manual ESD stations HS-1000, SIS logic solver UCP-1000 and UPS-1000, acting on ESDV-1001 / ESDV-1107 and the district-station ESD valves | F12: Detect a gas release in the HP / MP system and isolate the gas inventory automatically or on manual demand | G12: SIS per SRS-GN-001; ESD valves fail-closed; UPS 30 min | H12: Normally on line; detectors 20 % / 40 % LEL alarm / trip | I12: Materials: Natural gas
A13: N09 | C13: =IF(B13="","",A13&" – "&B13)
A14: N10 | C14: =IF(B14="","",A14&" – "&B14)
A15: N11 | C15: =IF(B15="","",A15&" – "&B15)
A16: N12 | C16: =IF(B16="","",A16&" – "&B16)
A17: N13 | C17: =IF(B17="","",A17&" – "&B17)
A18: N14 | C18: =IF(B18="","",A18&" – "&B18)
A19: N15 | C19: =IF(B19="","",A19&" – "&B19)
A20: N16 | C20: =IF(B20="","",A20&" – "&B20)
A21: N17 | C21: =IF(B21="","",A21&" – "&B21)
A22: N18 | C22: =IF(B22="","",A22&" – "&B22)
A23: N19 | C23: =IF(B23="","",A23&" – "&B23)
A24: N20 | C24: =IF(B24="","",A24&" – "&B24)
... A34: N30 | C34: =IF(B34="","",A34&" – "&B34)

Sheet Lists
A1: DROP-DOWN LISTS
A2: Source: HAZOP Guidewords – Chemical, Steel & Metals. To add a cause, INSERT a row inside its key block (keys must stay grouped). [C] = mainly chemical, [S] = mainly steel & metals.
A4: Parameters | C4: Parameter | D4: Guideword | E4: Key | F4: Typical deviation (from guideword guide) | H4: Key (parameter|guideword) | I4: Potential cause | K4: Guideword | L4: Meaning | N4: PSI category | P4: IPL?
A5: Flow | C5: Flow | D5: NO | E5: Flow|NO | F5: No flow | H5: Flow|NO | I5: Empty source vessel, feed tank, bin or gas holder | K5: NO | L5: Complete negation of intent | N5: Drawings | P5: Yes
A6: Pressure | C6: Flow | D6: REVERSE | E6: Flow|REVERSE | F6: Reverse flow | H6: Flow|NO | I6: Wrong routing / incorrect valve line-up | K6: MORE | L6: Quantitative increase | N6: Process technology | P6: No
A7: Temperature | C7: Flow | D7: MORE | E7: Flow|MORE | F7: More flow | H7: Flow|NO | I7: Blockage, gas lock or vapour lock | K7: LESS | L7: Quantitative decrease | N7: Hazardous materials
A8: Level | C8: Flow | D8: LESS | E8: Flow|LESS | F8: Less flow | H8: Flow|NO | I8: Slip plate / spectacle blind left in or incorrectly installed | K8: AS WELL AS | L8: Something additional present | N8: Equipment
A9: Composition | C9: Flow | D9: OTHER THAN | E9: Flow|OTHER THAN | F9: Misdirected flow (Other than – wrong destination) | H9: Flow|NO | I9: Non-return valve fitted the wrong way round | K9: PART OF | L9: Only part of intent achieved | N9: Procedures
A10: Phase | C10: Flow | D10: AS WELL AS | E10: Flow|AS WELL AS | F10: As well as (additional material or phase in the flow) | H10: Flow|NO | I10: Burst pipe or large leak upstream | K10: REVERSE | L10: Logical opposite | N10: Previous studies
A11: Reaction | C11: Pressure | D11: MORE | E11: Pressure|MORE | F11: More pressure | H11: Flow|NO | I11: Equipment failure – control valve fails closed, isolation valve, pump or compressor trip, vessel failure | K11: OTHER THAN | L11: Complete substitution | N11: Other
A12: Mixing / agitation | C12: Pressure | D12: LESS | E12: Pressure|LESS | F12: Less pressure (vacuum) | H12: Flow|NO | I12: Incorrect pressure differential (downstream pressure higher than upstream) | K12: EARLY | L12: Relative to clock time
A13: Timing / sequence | C13: Pressure | D13: FLUCTUATING | E13: Pressure|FLUCTUATING | F13: Pressure fluctuation / surge | H13: Flow|NO | I13: Isolation in error (wrong valve closed, LOTO on wrong equipment) | K13: LATE | L13: Relative to clock time
A14: Rate of change | C14: Temperature | D14: MORE | E14: Temperature|MORE | F14: More temperature | H14: Flow|NO | I14: Power failure; instrument air failure (valves go to fail position) | K14: BEFORE | L14: Relative to sequence
A15: Viscosity / density | C15: Temperature | D15: LESS | E15: Temperature|LESS | F15: Less temperature | H15: Flow|NO | I15: Control system / DCS / PLC failure; spurious trip | K15: AFTER | L15: Relative to sequence
A16: Molten metal / slag containment | C16: Level | D16: MORE | E16: Level|MORE | F16: High level | H16: Flow|NO | I16: Line frozen or solidified (loss of heat tracing or jacket heating) | K16: FASTER | L16: Rate of step / change
A17: Water contact with molten metal / slag | C17: Level | D17: LESS | E17: Level|LESS | F17: Low level / no level | H17: Flow|NO | I17: [C] Polymerisation, crystallisation or hydrate formation in the line | K17: SLOWER | L17: Rate of step / change
A18: Cooling water flow (water-cooled elements) | C18: Level | D18: NO | E18: Level|NO | F18: Low level / no level | H18: Flow|NO | I18: [S] Molten metal or slag frozen in launder, runner, tap hole or nozzle (skull formation) | K18: FLUCTUATING | L18: Unstable / surging
A19: Water-cooled element integrity | C19: Composition | D19: AS WELL AS | E19: Composition|AS WELL AS | F19: Contamination / composition change (As well as) | H19: Flow|NO | I19: [S] Blocked tuyere, lance tip, burner or porous plug | K19: LOSS OF | L19: Loss of function or containment
A20: Process gas (CO, H2 – BFG, COG, LD gas, reducing gas) | C20: Composition | D20: PART OF | E20: Composition|PART OF | F20: Part of (wrong ratio / concentration) | H20: Flow|NO | I20: [S] Bridging / hang-up of burden, DRI, pellets or scrap in bins, chutes or shaft furnace | K20: LEAK OF | L20: Release from containment
A21: Air / oxygen in process gas | C21: Composition | D21: OTHER THAN | E21: Composition|OTHER THAN | F21: Other than (wrong material) | H21: Flow|NO | I21: [S] Conveyor, feeder or vibratory feeder stopped (belt tear, drive trip, chute blockage) | K21: INADEQUATE | L21: Auxiliary topic not adequately provided
A22: Oxygen (lances, burners, pipelines) | C22: Phase | D22: OTHER THAN | E22: Phase|OTHER THAN | F22: Unintended phase change | H22: Flow|REVERSE | I22: Defective or passing non-return valve | K22: REVIEW | L22: Overview topic (whole-study review)
A23: Inert gas (N2, Ar) | C23: Reaction | D23: MORE | E23: Reaction|MORE | F23: More reaction / runaway | H23: Flow|REVERSE | I23: Siphon effect
A24: Electrical energy (furnace / electrolysis) | C24: Reaction | D24: LESS | E24: Reaction|LESS | F24: Less / no reaction | H24: Flow|REVERSE | I24: Incorrect differential pressure
A25: Solid charge materials | C25: Reaction | D25: NO | E25: Reaction|NO | F25: Less / no reaction | H25: Flow|REVERSE | I25: Two-way flow in common headers
A26: Hot DRI / HBI temperature | C26: Reaction | D26: OTHER THAN | E26: Reaction|OTHER THAN | F26: Unwanted side reaction (Other than) | H26: Flow|REVERSE | I26: Poor isolation / passing valves
A27: Combustible dust | C27: Mixing / agitation | D27: NO | E27: Mixing / agitation|NO | F27: No / less / more mixing | H27: Flow|REVERSE | I27: Emergency venting or depressurisation
A28: Hydraulic / lube oil | C28: Mixing / agitation | D28: LESS | E28: Mixing / agitation|LESS | F28: No / less / more mixing | H28: Flow|REVERSE | I28: Incorrect operation (valve opened out of sequence)
A29: Load control (cranes, ladle / transfer cars) | C29: Mixing / agitation | D29: MORE | E29: Mixing / agitation|MORE | F29: No / less / more mixing | H29: Flow|REVERSE | I29: Pump failure or pump running in reverse (wrong rotation after motor rewiring)
A30: Casting speed / mould level | C30: Timing / sequence | D30: EARLY | E30: Timing / sequence|EARLY | F30: Early / late / before / after / step omitted | H30: Flow|REVERSE | I30: [C] Process fluid backflow into utility lines (nitrogen, steam, cooling water, potable water) when utility pressure is lower than process
A31: Refractory | C31: Timing / sequence | D31: LATE | E31: Timing / sequence|LATE | F31: Early / late / before / after / step omitted | H31: Flow|REVERSE | I31: [S] CO-rich process gas (BFG, COG, BOF/LD gas, DRI top gas) backflowing into nitrogen, air or steam headers
A32: Pickling acid / zinc bath | C32: Timing / sequence | D32: BEFORE | E32: Timing / sequence|BEFORE | F32: Early / late / before / after / step omitted | H32: Flow|REVERSE | I32: [S] Flashback in fuel-gas, oxygen or oxy-fuel lines (flame arrestor missing or failed)
A33: Relief | C33: Timing / sequence | D33: AFTER | E33: Timing / sequence|AFTER | F33: Early / late / before / after / step omitted | H33: Flow|REVERSE | I33: [S] Loss of water seal / seal pot allowing gas back-flow into the plant or atmosphere
A34: Process control / instrumentation | C34: Timing / sequence | D34: NO | E34: Timing / sequence|NO | F34: Early / late / before / after / step omitted | H34: Flow|REVERSE | I34: [S] Reverse flow of cooling water due to loss of pump with elevated header (draining of cooling circuits)
... A61: Layout and facility siting | C61: Casting speed / mould level | D61: MORE | E61: Casting speed / mould level|MORE | F61: Casting speed / mould level / product handling deviations | H61: Flow|LESS | I61: [S] Dust build-up in off-gas ducts, fans, baghouses or venturi scrubbers
C62: Casting speed / mould level | D62: LESS | E62: Casting speed / mould level|LESS | F62: Casting speed / mould level / product handling deviations | H62: Flow|OTHER THAN | I62: Cross-connection between systems; wrong hose connected
C63: Refractory | D63: LESS | E63: Refractory|LESS | F63: Less / failed refractory | H63: Flow|OTHER THAN | I63: Road / rail tanker discharged into wrong storage tank
C64: Pickling acid / zinc bath | D64: MORE | E64: Pickling acid / zinc bath|MORE | F64: Concentration / temperature / contamination deviations | H64: Flow|OTHER THAN | I64: Drain or vent valves left open
C65: Pickling acid / zinc bath | D65: LESS | E65: Pickling acid / zinc bath|LESS | F65: Concentration / temperature / contamination deviations | H65: Flow|OTHER THAN | I65: Utility station connected to process (nitrogen hose left connected)
C66: Pickling acid / zinc bath | D66: AS WELL AS | E66: Pickling acid / zinc bath|AS WELL AS | F66: Concentration / temperature / contamination deviations | H66: Flow|OTHER THAN | I66: [S] Molten metal or slag spilled outside ladle, pot or mould (ladle misaligned, crane positioning error, tilting over-travel)
C67: Relief | D67: INADEQUATE | E67: Relief|INADEQUATE | F67: Inadequate / inappropriate relief | H67: Flow|OTHER THAN | I67: [S] Slag carry-over into ladle or tundish
...

Sheet Risk Matrix
A1: RISK MATRIX (5 x 5)
A2: Risk score = value in the matrix cell for Severity (row) x Likelihood (column). Default scores are S x L (1–25); overwrite the yellow cells to use your company's matrix.
C3: LIKELIHOOD →
B4: Severity \ Likelihood | C4: 1 – Rare | D4: 2 – Unlikely | E4: 3 – Possible | F4: 4 – Likely | G4: 5 – Almost certain
A5: SEVERITY ↓ | B5: 5 – Catastrophic | C5: 5 | D5: 10 | E5: 15 | F5: 20 | G5: 25
B6: 4 – Major | C6: 4 | D6: 8 | E6: 12 | F6: 16 | G6: 20
B7: 3 – Moderate | C7: 3 | D7: 6 | E7: 9 | F7: 12 | G7: 15
B8: 2 – Minor | C8: 2 | D8: 4 | E8: 6 | F8: 8 | G8: 10
B9: 1 – Negligible | C9: 1 | D9: 2 | E9: 3 | F9: 4 | G9: 5
B11: Risk bands (minimum score):
B12: Low | C12: 1 | D12: Tolerable – manage by procedures
B13: Medium | C13: 5 | D13: Tolerable if ALARP – review safeguards
B14: High | C14: 10 | D14: Recommendation required to reduce risk
B15: Very High | C15: 20 | D15: Intolerable – mandatory risk reduction
B18: Severity level | C18: People | D18: Environment | E18: Asset / production
B19: 1 – Negligible | C19: First aid case; no lost time | D19: Minor release contained on site; no impact | E19: Negligible damage / production loss
B20: 2 – Minor | C20: Medical treatment case / restricted work | D20: Reportable release, contained on site, short-term impact | E20: Minor damage; short production loss
B21: 3 – Moderate | C21: Lost-time injury; reversible health effect | D21: Off-site release with short-term impact | E21: Significant damage; production loss of days
B22: 4 – Major | C22: Single fatality or permanent disability | D22: Off-site release with significant medium-term impact | E22: Major damage; extended production loss
B23: 5 – Catastrophic | C23: Multiple fatalities; off-site injuries | D23: Major off-site release; long-term environmental damage | E23: Loss of unit / plant; extended outage
B25: Likelihood level | C25: Description
B26: 1 – Rare | C26: Not expected to occur in the life of the facility (< 1 in 10 000 years)
B27: 2 – Unlikely | C27: Has occurred in the industry; not expected here (1 in 1 000 – 10 000 years)
B28: 3 – Possible | C28: Could occur in the life of the facility (1 in 100 – 1 000 years)
B29: 4 – Likely | C29: Expected to occur several times in the life of the facility (1 in 10 – 100 years)
B30: 5 – Almost certain | C30: Expected to occur within the year (> 1 in 10 years)
B32: Descriptors and frequencies are typical examples – replace with the client's approved risk matrix before the study.

Sheet Node 01
A1: HAZOP WORKSHEET | E1: =Cover!B7
A3: Select node ▸ | D3: N01 – Gas receiving & metering station (GRMS) | M3: Session date | N3: 46307 | P3: Revision | Q3: A
A4: Node title | D4: =IF($D$3="","",IFERROR(INDEX(Nodes!$B$5:$B$34,MATCH($D$3,Nodes!$C$5:$C$34,0))&"",""))
A5: P&IDs / drawings | D5: =IF($D$3="","",IFERROR(INDEX(Nodes!$D$5:$D$34,MATCH($D$3,Nodes!$C$5:$C$34,0))&"",""))
A6: Battery limits | D6: =IF($D$3="","",IFERROR(INDEX(Nodes!$E$5:$E$34,MATCH($D$3,Nodes!$C$5:$C$34,0))&"",""))
A7: Functional description / design intent | D7: =IF($D$3="","",IFERROR(INDEX(Nodes!$F$5:$F$34,MATCH($D$3,Nodes!$C$5:$C$34,0))&"",""))
A8: Design parameters | D8: =IF($D$3="","",IFERROR(INDEX(Nodes!$G$5:$G$34,MATCH($D$3,Nodes!$C$5:$C$34,0))&"",""))
A9: Operating parameters | D9: =IF($D$3="","",IFERROR(INDEX(Nodes!$H$5:$H$34,MATCH($D$3,Nodes!$C$5:$C$34,0))&"",""))
A11: ONE ROW PER DEVIATION. Choose Parameter + Guideword, then pick up to 6 causes in Cause 1–6 (or type your own) – they are listed line by line in 'Potential causes'. Enter up to 6 safeguards, each marked IPL Yes/No – listed in 'Safeguards'. Use the [–] buttons above the columns to collapse the pick columns.
A12: DEVIATION | E12: CAUSE PICK-LIST | K12: CAUSES & CONSEQUENCES | M12: RISK BEFORE SAFEGUARDS | Q12: SAFEGUARD ENTRY (mark each IPL Yes / No) | AC12: SAFEGUARDS | AE12: RISK AFTER SAFEGUARDS | AI12: RECOMMENDATIONS
A13: Dev. No. | B13: Parameter | C13: Guideword | D13: Deviation | E13: Cause 1 | F13: Cause 2 | G13: Cause 3 | H13: Cause 4 | I13: Cause 5 | J13: Cause 6 | K13: Potential causes | L13: Consequences | M13: Severity (S) | N13: Likelihood (L) | O13: Risk score | P13: Risk rank | Q13: Safeguard 1 | R13: IPL? 1 | S13: Safeguard 2 | T13: IPL? 2 | U13: Safeguard 3 | V13: IPL? 3 | W13: Safeguard 4 | X13: IPL? 4 | Y13: Safeguard 5 | Z13: IPL? 5 | AA13: Safeguard 6 | AB13: IPL? 6 | AC13: Safeguards | AD13: No. of IPLs | AE13: Severity (S) | AF13: Likelihood (L) | AG13: Risk score | AH13: Risk rank | AI13: Recommendations / actions | AJ13: Action by
A14: =IF(B14="","",COUNTIF(B$14:B14,"?*")) | B14: Flow | C14: NO | D14: =IF(OR(B14="",C14=""),"",UPPER(LEFT(C14,1))&LOWER(MID(C14,2,30))&" "&LOWER(LEFT(B14,1))&MID(B14,2,200)) | E14: Supplier pipeline trip / supplier ESD | F14: Spurious closure of ESDV-1001 (solenoid, power or air failure) | G14: Both filter-separators F-1002A/B blocked (black powder) | K14: =_xlfn.TEXTJOIN(CHAR(10),TRUE,IF(E14="","","• "&E14),IF(F14="","","• "&F14),IF(G14="","","• "&G14),IF(H14="","","• "&H14),IF(I14="","","• "&I14),IF(J14="","","• "&J14)) | L14: Loss of gas to all users: reformer, reheat furnace, preheater and oxy-fuel burner flame-outs and trips; on uncontrolled restoration of supply, gas may enter burners that are not proven shut – accumulation and explosion on relight (see N06-01); production loss [N01-01] Restoration after an interruption is the hazardous phase – see N06 and R-006. | M14: 3 – Moderate | N14: 3 – Possible | O14: =IF(OR(M14="",N14=""),"",INDEX(RiskGrid,6-VALUE(LEFT(M14,1)),VALUE(LEFT(N14,1)))) | P14: =IF(O14="","",IF(O14>=BandVH,"Very High",IF(O14>=BandHigh,"High",IF(O14>=BandMed,"Medium","Low")))) | Q14: PSLL-2006 / PSLL-4005 – Low-low gas pressure trips in the user burner management systems (reformer, reheat furnace, preheaters) | R14: Yes | S14: F-1002A/B – Duty / standby filter-separators with LSH-1002 high-liquid alarm and PDIT-1002 differential-pressure alarm | T14: No | U14: Gas supply agreement quality specification; supplier notification of off-spec gas and supply interruptions | V14: No | AC14: =_xlfn.TEXTJOIN(CHAR(10),TRUE,IF(Q14="","","• "&Q14&IF(R14="Yes"," [IPL]","")),IF(S14="","","• "&S14&IF(T14="Yes"," [IPL]","")),IF(U14="","","• "&U14&IF(V14="Yes"," [IPL]","")),IF(W14="","","• "&W14&IF(X14="Yes"," [IPL]","")),IF(Y14="","","• "&Y14&IF(Z14="Yes"," [IPL]","")),IF(AA14="","","• "&AA14&IF(AB14="Yes"," [IPL]",""))) | AD14: =IF(AC14="","",COUNTIF(Q14:AB14,"Yes")) | AE14: 3 – Moderate | AF14: 2 – Unlikely | AG14: =IF(OR(AE14="",AF14=""),"",INDEX(RiskGrid,6-VALUE(LEFT(AE14,1)),VALUE(LEFT(AF14,1)))) | AH14: =IF(AG14="","",IF(AG14>=BandVH,"Very High",IF(AG14>=BandHigh,"High",IF(AG14>=BandMed,"Medium","Low")))) | AI14: R-006 Agree a supply-interruption and restoration protocol with the gas supplier: users isolated before re-pressurisation, controlled restoration sequence, BMS re-start only after confirmed header pressure. | AJ14: Utilities manager
A15: =IF(B15="","",COUNTIF(B$14:B15,"?*")) | B15: Pressure | C15: MORE | D15: =IF(OR(B15="",C15=""),"",UPPER(LEFT(C15,1))&LOWER(MID(C15,2,30))&" "&LOWER(LEFT(B15,1))&MID(B15,2,200)) | E15: Failed-open pressure control valves (PCVs) | F15: Supplier pressure excursion above normal operating range | G15: Thermal expansion of trapped (blocked-in) liquid | K15: =_xlfn.TEXTJOIN(CHAR(10),TRUE,IF(E15="","","• "&E15),IF(F15="","","• "&F15),IF(G15="","","• "&G15),IF(H15="","","• "&H15),IF(I15="","","• "&I15),IF(J15="","","• "&J15)) | L15: Overpressure of filter-separators / meter runs only if their design pressure were below the pipeline MAOP; blocked-in sections heated by the sun – flange leak, release of high-pressure gas (bow tie BT-GN-01) [N01-02] GRMS designed for the pipeline MAOP (50 barg) – overpressure from the supplier not credible. | M15: 5 – Catastrophic | N15: 2 – Unlikely | O15: =IF(OR(M15="",N15=""),"",INDEX(RiskGrid,6-VALUE(LEFT(M15,1)),VALUE(LEFT(N15,1)))) | P15: =IF(O15="","",IF(O15>=BandVH,"Very High",IF(O15>=BandHigh,"High",IF(O15>=BandMed,"Medium","Low")))) | Q15: GRMS piping, filter-separators and meter runs designed for the pipeline MAOP (no overpressure from the supplier) | R15: Yes | S15: PSV-1006A/B – Filter-separator fire-case / thermal relief valves | T15: Yes | U15: PT-1005 – GRMS inlet pressure high alarm PAH-1005 with operator response | V15: No | AC15: =_xlfn.TEXTJOIN(CHAR(10),TRUE,IF(Q15="","","• "&Q15&IF(R15="Yes"," [IPL]","")),IF(S15="","","• "&S15&IF(T15="Yes"," [IPL]","")),IF(U15="","","• "&U15&IF(V15="Yes"," [IPL]","")),IF(W15="","","• "&W15&IF(X15="Yes"," [IPL]","")),IF(Y15="","","• "&Y15&IF(Z15="Yes"," [IPL]","")),IF(AA15="","","• "&AA15&IF(AB15="Yes"," [IPL]",""))) | AD15: =IF(AC15="","",COUNTIF(Q15:AB15,"Yes")) | AE15: 5 – Catastrophic | AF15: 1 – Rare | AG15: =IF(OR(AE15="",AF15=""),"",INDEX(RiskGrid,6-VALUE(LEFT(AE15,1)),VALUE(LEFT(AF15,1)))) | AH15: =IF(AG15="","",IF(AG15>=BandVH,"Very High",IF(AG15>=BandHigh,"High",IF(AG15>=BandMed,"Medium","Low"))))
A16: =IF(B16="","",COUNTIF(B$14:B16,"?*")) | B16: Flow | C16: AS WELL AS | D16: =IF(OR(B16="",C16=""),"",UPPER(LEFT(C16,1))&LOWER(MID(C16,2,30))&" "&LOWER(LEFT(B16,1))&MID(B16,2,200)) | E16: Gas or air entrainment in liquid; liquid carry-over in gas | F16: Pigging debris and black powder from the supplier pipeline | G16: Condensate from the pipeline after cold weather / pigging | K16: =_xlfn.TEXTJOIN(CHAR(10),TRUE,IF(E16="","","• "&E16),IF(F16="","","• "&F16),IF(G16="","","• "&G16),IF(H16="","","• "&H16),IF(I16="","","• "&I16),IF(J16="","","• "&J16)) | L16: Filter-separator overload; liquid / dust carry-over to meters and regulator pilots – active regulator may stick open (demand on overpressure protection, N02-02); erosion; liquid slugs cause flame instability at burners [N01-03] Carry-over is one of the initiating causes in fault tree FT-GN-01 (active regulator fails open). | M16: 4 – Major | N16: 3 – Possible | O16: =IF(OR(M16="",N16=""),"",INDEX(RiskGrid,6-VALUE(LEFT(M16,1)),VALUE(LEFT(N16,1)))) | P16: =IF(O16="","",IF(O16>=BandVH,"Very High",IF(O16>=BandHigh,"High",IF(O16>=BandMed,"Medium","Low")))) | Q16: F-1002A/B – Duty / standby filter-separators with LSH-1002 high-liquid alarm and PDIT-1002 differential-pressure alarm | R16: No | S16: Operator rounds with portable gas detector; annual acoustic leak survey | T16: No | AC16: =_xlfn.TEXTJOIN(CHAR(10),TRUE,IF(Q16="","","• "&Q16&IF(R16="Yes"," [IPL]","")),IF(S16="","","• "&S16&IF(T16="Yes"," [IPL]","")),IF(U16="","","• "&U16&IF(V16="Yes"," [IPL]","")),IF(W16="","","• "&W16&IF(X16="Yes"," [IPL]","")),IF(Y16="","","• "&Y16&IF(Z16="Yes"," [IPL]","")),IF(AA16="","","• "&AA16&IF(AB16="Yes"," [IPL]",""))) | AD16: =IF(AC16="","",COUNTIF(Q16:AB16,"Yes")) | AE16: 4 – Major | AF16: 2 – Unlikely | AG16: =IF(OR(AE16="",AF16=""),"",INDEX(RiskGrid,6-VALUE(LEFT(AE16,1)),VALUE(LEFT(AF16,1)))) | AH16: =IF(AG16="","",IF(AG16>=BandVH,"Very High",IF(AG16>=BandHigh,"High",IF(AG16>=BandMed,"Medium","Low")))) | AI16: R-016 Route the filter-separator drains to a closed drain vessel instead of an open drain; review the LSH-1002 alarm response. | AJ16: Process engineer
A17: =IF(B17="","",COUNTIF(B$14:B17,"?*")) | B17: Composition | C17: OTHER THAN | D17: =IF(OR(B17="",C17=""),"",UPPER(LEFT(C17,1))&LOWER(MID(C17,2,30))&" "&LOWER(LEFT(B17,1))&MID(B17,2,200)) | E17: Wrong raw material delivered or unloaded | F17: H2S / higher hydrocarbons above the supply specification | G17: Wobbe index change (supplier gas source change) | K17: =_xlfn.TEXTJOIN(CHAR(10),TRUE,IF(E17="","","• "&E17),IF(F17="","","• "&F17),IF(G17="","","• "&G17),IF(H17="","","• "&H17),IF(I17="","","• "&I17),IF(J17="","","• "&J17)) | L17: H2S poisons the DRI reformer catalyst and is toxic on release; Wobbe index change alters burner heat release – over-firing or flame instability in the reheat furnace and preheaters [N01-04] Composition is also reviewed for the DRI plant in N04-04. | M17: 3 – Moderate | N17: 3 – Possible | O17: =IF(OR(M17="",N17=""),"",INDEX(RiskGrid,6-VALUE(LEFT(M17,1)),VALUE(LEFT(N17,1)))) | P17: =IF(O17="","",IF(O17>=BandVH,"Very High",IF(O17>=BandHigh,"High",IF(O17>=BandMed,"Medium","Low")))) | Q17: AT-1004 – Gas chromatograph – composition, Wobbe index and H2S monitoring with alarm | R17: No | S17: Gas supply agreement quality specification; supplier notification of off-spec gas and supply interruptions | T17: No | AC17: =_xlfn.TEXTJOIN(CHAR(10),TRUE,IF(Q17="","","• "&Q17&IF(R17="Yes"," [IPL]","")),IF(S17="","","• "&S17&IF(T17="Yes"," [IPL]","")),IF(U17="","","• "&U17&IF(V17="Yes"," [IPL]","")),IF(W17="","","• "&W17&IF(X17="Yes"," [IPL]","")),IF(Y17="","","• "&Y17&IF(Z17="Yes"," [IPL]","")),IF(AA17="","","• "&AA17&IF(AB17="Yes"," [IPL]",""))) | AD17: =IF(AC17="","",COUNTIF(Q17:AB17,"Yes")) | AE17: 3 – Moderate | AF17: 2 – Unlikely | AG17: =IF(OR(AE17="",AF17=""),"",INDEX(RiskGrid,6-VALUE(LEFT(AE17,1)),VALUE(LEFT(AF17,1)))) | AH17: =IF(AG17="","",IF(AG17>=BandVH,"Very High",IF(AG17>=BandHigh,"High",IF(AG17>=BandMed,"Medium","Low"))))
A18: =IF(B18="","",COUNTIF(B$14:B18,"?*")) | B18: Process gas (CO, H2 – BFG, COG, LD gas, reducing gas) | C18: LEAK OF | D18: =IF(OR(B18="",C18=""),"",UPPER(LEFT(C18,1))&LOWER(MID(C18,2,30))&" "&LOWER(LEFT(B18,1))&MID(B18,2,200)) | E18: Flange, valve or seal leak; water-seal blown | F18: Small-bore fitting fatigue (meter-run vibration) | G18: Pig receiver closure opened or leaking under pressure | K18: =_xlfn.TEXTJOIN(CHAR(10),TRUE,IF(E18="","","• "&E18),IF(F18="","","• "&F18),IF(G18="","","• "&G18),IF(H18="","","• "&H18),IF(I18="","","• "&I18),IF(J18="","","• "&J18)) | L18: High-pressure natural gas release fed from the pipeline inventory: jet fire if ignited immediately; flash fire or vapour cloud explosion if ignited later – potential multiple fatalities and loss of gas to the whole works (event tree ETA-GN-01) [N01-05] Quantified: bow tie BT-GN-01 (top event = loss of containment of the HP / MP system), event tree ETA-GN-01 (initiating event = BT-GN-01 top), fault tree FT-GN-02 (ESD). Likelihood after safeguards from the calculated frequency 4.3E-6 /yr. | M18: 5 – Catastrophic | N18: 3 – Possible | O18: =IF(OR(M18="",N18=""),"",INDEX(RiskGrid,6-VALUE(LEFT(M18,1)),VALUE(LEFT(N18,1)))) | P18: =IF(O18="","",IF(O18>=BandVH,"Very High",IF(O18>=BandHigh,"High",IF(O18>=BandMed,"Medium","Low")))) | Q18: UCP-1000 – Gas detection GD-1110A/B/C (2oo3) and ESD isolation of the HP / MP system – ESDV-1001 and ESDV-1107 close (SIS UCP-1000) | R18: Yes | S18: Ignition source control – hazardous area classification with Ex equipment, hot-work permit, vehicle control | T18: No | U18: PR-1001 – Pig receiver quick-opening closure with pressure-warning / locking device (key interlock with vent valve) | V18: Yes | W18: Separation distances and fire-proofing of supports in the GRMS / PRS | X18: No | Y18: Emergency response team / fire brigade; emergency response plan for gas releases and fires | Z18: No | AC18: =_xlfn.TEXTJOIN(CHAR(10),TRUE,IF(Q18="","","• "&Q18&IF(R18="Yes"," [IPL]","")),IF(S18="","","• "&S18&IF(T18="Yes"," [IPL]","")),IF(U18="","","• "&U18&IF(V18="Yes"," [IPL]","")),IF(W18="","","• "&W18&IF(X18="Yes"," [IPL]","")),IF(Y18="","","• "&Y18&IF(Z18="Yes"," [IPL]","")),IF(AA18="","","• "&AA18&IF(AB18="Yes"," [IPL]",""))) | AD18: =IF(AC18="","",COUNTIF(Q18:AB18,"Yes")) | AE18: 5 – Catastrophic | AF18: 1 – Rare | AG18: =IF(OR(AE18="",AF18=""),"",INDEX(RiskGrid,6-VALUE(LEFT(AE18,1)),VALUE(LEFT(AF18,1)))) | AH18: =IF(AG18="","",IF(AG18>=BandVH,"Very High",IF(AG18>=BandHigh,"High",IF(AG18>=BandMed,"Medium","Low")))) | AI18: R-001 Verify the HP / MP gas detection & ESD function against the required risk reduction. Fault tree FT-GN-02 gives PFDavg 2.6E-2 (RRF 38); test the effect of six-monthly partial-stroke testing of ESDV-1001 / ESDV-1107 and quarterly detector bump tests (FMECA S01 / S08). R-017 Verify the pig-receiver quick-opening closure safety device (pressure-warning / key interlock with the vent valve) and include it in the pigging procedure and its training. R-021 Assess the vapour cloud explosion overpressure at the PRS / GRMS and verify the siting of the utilities control room (bow tie BT-GN-01 / event tree ETA-GN-01 VCE end state). | AJ18: Instrument engineer / Mechanical engineer / HSE / process safety
A19: =IF(B19="","",COUNTIF(B$14:B19,"?*")) | B19: Corrosion / erosion | C19: MORE | D19: =IF(OR(B19="",C19=""),"",UPPER(LEFT(C19,1))&LOWER(MID(C19,2,30))&" "&LOWER(LEFT(B19,1))&MID(B19,2,200)) | E19: Cathodic protection arrangements inadequate | F19: Insulating joint IJ-1001 shorted (debris, bonding cable) | G19: Coating damage at road crossings | K19: =_xlfn.TEXTJOIN(CHAR(10),TRUE,IF(E19="","","• "&E19),IF(F19="","","• "&F19),IF(G19="","","• "&G19),IF(H19="","","• "&H19),IF(I19="","","• "&I19),IF(J19="","","• "&J19)) | L19: Wall loss leading to a leak or rupture of the buried section – gas migrates through soil into trenches / buildings (bow tie BT-GN-01 threat 2) [N01-06] FMECA S03 CP-1200; bow tie BT-GN-01 threat T2. | M19: 5 – Catastrophic | N19: 3 – Possible | O19: =IF(OR(M19="",N19=""),"",INDEX(RiskGrid,6-VALUE(LEFT(M19,1)),VALUE(LEFT(N19,1)))) | P19: =IF(O19="","",IF(O19>=BandVH,"Very High",IF(O19>=BandHigh,"High",IF(O19>=BandMed,"Medium","Low")))) | Q19: CP-1200 – Coating and impressed-current cathodic protection of buried sections; annual CP / DCVG survey | R19: No | S19: Piping inspection programme – thickness monitoring at supports, rack crossings and low points | T19: No | AC19: =_xlfn.TEXTJOIN(CHAR(10),TRUE,IF(Q19="","","• "&Q19&IF(R19="Yes"," [IPL]","")),IF(S19="","","• "&S19&IF(T19="Yes"," [IPL]","")),IF(U19="","","• "&U19&IF(V19="Yes"," [IPL]","")),IF(W19="","","• "&W19&IF(X19="Yes"," [IPL]","")),IF(Y19="","","• "&Y19&IF(Z19="Yes"," [IPL]","")),IF(AA19="","","• "&AA19&IF(AB19="Yes"," [IPL]",""))) | AD19: =IF(AC19="","",COUNTIF(Q19:AB19,"Yes")) | AE19: 5 – Catastrophic | AF19: 2 – Unlikely | AG19: =IF(OR(AE19="",AF19=""),"",INDEX(RiskGrid,6-VALUE(LEFT(AE19,1)),VALUE(LEFT(AF19,1)))) | AH19: =IF(AG19="","",IF(AG19>=BandVH,"Very High",IF(AG19>=BandHigh,"High",IF(AG19>=BandMed,"Medium","Low")))) | AI19: R-008 Survey stray currents and induced voltages on gas pipework near the EAF / LF high-current systems; verify insulating joints and bonding; include in CP interference testing. | AJ19: Electrical engineer
A20: =IF(B20="","",COUNTIF(B$14:B20,"?*")) | B20: Maintenance | C20: INADEQUATE | D20: =IF(OR(B20="",C20=""),"",UPPER(LEFT(C20,1))&LOWER(MID(C20,2,30))&" "&LOWER(LEFT(B20,1))&MID(B20,2,200)) | E20: Isolation, drainage, purging | F20: Pig receiver opened before full depressurisation | G20: Work permit system | K20: =_xlfn.TEXTJOIN(CHAR(10),TRUE,IF(E20="","","• "&E20),IF(F20="","","• "&F20),IF(G20="","","• "&G20),IF(H20="","","• "&H20),IF(I20="","","• "&I20),IF(J20="","","• "&J20)) | L20: Pig receiver door blown open or gas release onto the operator; pyrophoric iron sulphide in pig debris ignites on exposure to air [N01-07] Bow tie BT-GN-01 threat T5 (maintenance error). | M20: 5 – Catastrophic | N20: 3 – Possible | O20: =IF(OR(M20="",N20=""),"",INDEX(RiskGrid,6-VALUE(LEFT(M20,1)),VALUE(LEFT(N20,1)))) | P20: =IF(O20="","",IF(O20>=BandVH,"Very High",IF(O20>=BandHigh,"High",IF(O20>=BandMed,"Medium","Low")))) | Q20: PR-1001 – Pig receiver quick-opening closure with pressure-warning / locking device (key interlock with vent valve) | R20: Yes | S20: Pigging procedure OP-GN-010: depressurise, N2 purge and gas test before opening the pig receiver | T20: No | U20: Permit-to-work with isolation verification (DBB / spades), gas-free test and fire watch | V20: No | AC20: =_xlfn.TEXTJOIN(CHAR(10),TRUE,IF(Q20="","","• "&Q20&IF(R20="Yes"," [IPL]","")),IF(S20="","","• "&S20&IF(T20="Yes"," [IPL]","")),IF(U20="","","• "&U20&IF(V20="Yes"," [IPL]","")),IF(W20="","","• "&W20&IF(X20="Yes"," [IPL]","")),IF(Y20="","","• "&Y20&IF(Z20="Yes"," [IPL]","")),IF(AA20="","","• "&AA20&IF(AB20="Yes"," [IPL]",""))) | AD20: =IF(AC20="","",COUNTIF(Q20:AB20,"Yes")) | AE20: 5 – Catastrophic | AF20: 1 – Rare | AG20: =IF(OR(AE20="",AF20=""),"",INDEX(RiskGrid,6-VALUE(LEFT(AE20,1)),VALUE(LEFT(AF20,1)))) | AH20: =IF(AG20="","",IF(AG20>=BandVH,"Very High",IF(AG20>=BandHigh,"High",IF(AG20>=BandMed,"Medium","Low")))) | AI20: R-017 Verify the pig-receiver quick-opening closure safety device (pressure-warning / key interlock with the vent valve) and include it in the pigging procedure and its training. | AJ20: Mechanical engineer
A21: =IF(B21="","",COUNTIF(B$14:B21,"?*")) | D21: =IF(OR(B21="",C21=""),"",UPPER(LEFT(C21,1))&LOWER(MID(C21,2,30))&" "&LOWER(LEFT(B21,1))&MID(B21,2,200)) | K21: =_xlfn.TEXTJOIN(CHAR(10),TRUE,IF(E21="","","• "&E21),IF(F21="","","• "&F21),IF(G21="","","• "&G21),IF(H21="","","• "&H21),IF(I21="","","• "&I21),IF(J21="","","• "&J21)) | O21: =IF(OR(M21="",N21=""),"",INDEX(RiskGrid,6-VALUE(LEFT(M21,1)),VALUE(LEFT(N21,1)))) | P21: =IF(O21="","",IF(O21>=BandVH,"Very High",IF(O21>=BandHigh,"High",IF(O21>=BandMed,"Medium","Low")))) | AC21: =_xlfn.TEXTJOIN(CHAR(10),TRUE,IF(Q21="","","• "&Q21&IF(R21="Yes"," [IPL]","")),IF(S21="","","• "&S21&IF(T21="Yes"," [IPL]","")),IF(U21="","","• "&U21&IF(V21="Yes"," [IPL]","")),IF(W21="","","• "&W21&IF(X21="Yes"," [IPL]","")),IF(Y21="","","• "&Y21&IF(Z21="Yes"," [IPL]","")),IF(AA21="","","• "&AA21&IF(AB21="Yes"," [IPL]",""))) | AD21: =IF(AC21="","",COUNTIF(Q21:AB21,"Yes")) | AG21: =IF(OR(AE21="",AF21=""),"",INDEX(RiskGrid,6-VALUE(LEFT(AE21,1)),VALUE(LEFT(AF21,1)))) | AH21: =IF(AG21="","",IF(AG21>=BandVH,"Very High",IF(AG21>=BandHigh,"High",IF(AG21>=BandMed,"Medium","Low"))))
A22: =IF(B22="","",COUNTIF(B$14:B22,"?*")) | D22: =IF(OR(B22="",C22=""),"",UPPER(LEFT(C22,1))&LOWER(MID(C22,2,30))&" "&LOWER(LEFT(B22,1))&MID(B22,2,200)) | K22: =_xlfn.TEXTJOIN(CHAR(10),TRUE,IF(E22="","","• "&E22),IF(F22="","","• "&F22),IF(G22="","","• "&G22),IF(H22="","","• "&H22),IF(I22="","","• "&I22),IF(J22="","","• "&J22)) | O22: =IF(OR(M22="",N22=""),"",INDEX(RiskGrid,6-VALUE(LEFT(M22,1)),VALUE(LEFT(N22,1)))) | P22: =IF(O22="","",IF(O22>=BandVH,"Very High",IF(O22>=BandHigh,"High",IF(O22>=BandMed,"Medium","Low")))) | AC22: =_xlfn.TEXTJOIN(CHAR(10),TRUE,IF(Q22="","","• "&Q22&IF(R22="Yes"," [IPL]","")),IF(S22="","","• "&S22&IF(T22="Yes"," [IPL]","")),IF(U22="","","• "&U22&IF(V22="Yes"," [IPL]","")),IF(W22="","","• "&W22&IF(X22="Yes"," [IPL]","")),IF(Y22="","","• "&Y22&IF(Z22="Yes"," [IPL]","")),IF(AA22="","","• "&AA22&IF(AB22="Yes"," [IPL]",""))) | AD22: =IF(AC22="","",COUNTIF(Q22:AB22,"Yes")) | AG22: =IF(OR(AE22="",AF22=""),"",INDEX(RiskGrid,6-VALUE(LEFT(AE22,1)),VALUE(LEFT(AF22,1)))) | AH22: =IF(AG22="","",IF(AG22>=BandVH,"Very High",IF(AG22>=BandHigh,"High",IF(AG22>=BandMed,"Medium","Low"))))
A23: =IF(B23="","",COUNTIF(B$14:B23,"?*")) | D23: =IF(OR(B23="",C23=""),"",UPPER(LEFT(C23,1))&LOWER(MID(C23,2,30))&" "&LOWER(LEFT(B23,1))&MID(B23,2,200)) | K23: =_xlfn.TEXTJOIN(CHAR(10),TRUE,IF(E23="","","• "&E23),IF(F23="","","• "&F23),IF(G23="","","• "&G23),IF(H23="","","• "&H23),IF(I23="","","• "&I23),IF(J23="","","• "&J23)) | O23: =IF(OR(M23="",N23=""),"",INDEX(RiskGrid,6-VALUE(LEFT(M23,1)),VALUE(LEFT(N23,1)))) | P23: =IF(O23="","",IF(O23>=BandVH,"Very High",IF(O23>=BandHigh,"High",IF(O23>=BandMed,"Medium","Low")))) | AC23: =_xlfn.TEXTJOIN(CHAR(10),TRUE,IF(Q23="","","• "&Q23&IF(R23="Yes"," [IPL]","")),IF(S23="","","• "&S23&IF(T23="Yes"," [IPL]","")),IF(U23="","","• "&U23&IF(V23="Yes"," [IPL]","")),IF(W23="","","• "&W23&IF(X23="Yes"," [IPL]","")),IF(Y23="","","• "&Y23&IF(Z23="Yes"," [IPL]","")),IF(AA23="","","• "&AA23&IF(AB23="Yes"," [IPL]",""))) | AD23: =IF(AC23="","",COUNTIF(Q23:AB23,"Yes")) | AG23: =IF(OR(AE23="",AF23=""),"",INDEX(RiskGrid,6-VALUE(LEFT(AE23,1)),VALUE(LEFT(AF23,1)))) | AH23: =IF(AG23="","",IF(AG23>=BandVH,"Very High",IF(AG23>=BandHigh,"High",IF(AG23>=BandMed,"Medium","Low"))))
A24: =IF(B24="","",COUNTIF(B$14:B24,"?*")) | D24: =IF(OR(B24="",C24=""),"",UPPER(LEFT(C24,1))&LOWER(MID(C24,2,30))&" "&LOWER(LEFT(B24,1))&MID(B24,2,200)) | K24: =_xlfn.TEXTJOIN(CHAR(10),TRUE,IF(E24="","","• "&E24),IF(F24="","","• "&F24),IF(G24="","","• "&G24),IF(H24="","","• "&H24),IF(I24="","","• "&I24),IF(J24="","","• "&J24)) | O24: =IF(OR(M24="",N24=""),"",INDEX(RiskGrid,6-VALUE(LEFT(M24,1)),VALUE(LEFT(N24,1)))) | P24: =IF(O24="","",IF(O24>=BandVH,"Very High",IF(O24>=BandHigh,"High",IF(O24>=BandMed,"Medium","Low")))) | AC24: =_xlfn.TEXTJOIN(CHAR(10),TRUE,IF(Q24="","","• "&Q24&IF(R24="Yes"," [IPL]","")),IF(S24="","","• "&S24&IF(T24="Yes"," [IPL]","")),IF(U24="","","• "&U24&IF(V24="Yes"," [IPL]","")),IF(W24="","","• "&W24&IF(X24="Yes"," [IPL]","")),IF(Y24="","","• "&Y24&IF(Z24="Yes"," [IPL]","")),IF(AA24="","","• "&AA24&IF(AB24="Yes"," [IPL]",""))) | AD24: =IF(AC24="","",COUNTIF(Q24:AB24,"Yes")) | AG24: =IF(OR(AE24="",AF24=""),"",INDEX(RiskGrid,6-VALUE(LEFT(AE24,1)),VALUE(LEFT(AF24,1)))) | AH24: =IF(AG24="","",IF(AG24>=BandVH,"Very High",IF(AG24>=BandHigh,"High",IF(AG24>=BandMed,"Medium","Low"))))
A25: =IF(B25="","",COUNTIF(B$14:B25,"?*")) | D25: =IF(OR(B25="",C25=""),"",UPPER(LEFT(C25,1))&LOWER(MID(C25,2,30))&" "&LOWER(LEFT(B25,1))&MID(B25,2,200)) | K25: =_xlfn.TEXTJOIN(CHAR(10),TRUE,IF(E25="","","• "&E25),IF(F25="","","• "&F25),IF(G25="","","• "&G25),IF(H25="","","• "&H25),IF(I25="","","• "&I25),IF(J25="","","• "&J25)) | O25: =IF(OR(M25="",N25=""),"",INDEX(RiskGrid,6-VALUE(LEFT(M25,1)),VALUE(LEFT(N25,1)))) | P25: =IF(O25="","",IF(O25>=BandVH,"Very High",IF(O25>=BandHigh,"High",IF(O25>=BandMed,"Medium","Low")))) | AC25: =_xlfn.TEXTJOIN(CHAR(10),TRUE,IF(Q25="","","• "&Q25&IF(R25="Yes"," [IPL]","")),IF(S25="","","• "&S25&IF(T25="Yes"," [IPL]","")),IF(U25="","","• "&U25&IF(V25="Yes"," [IPL]","")),IF(W25="","","• "&W25&IF(X25="Yes"," [IPL]","")),IF(Y25="","","• "&Y25&IF(Z25="Yes"," [IPL]","")),IF(AA25="","","• "&AA25&IF(AB25="Yes"," [IPL]",""))) | AD25: =IF(AC25="","",COUNTIF(Q25:AB25,"Yes")) | AG25: =IF(OR(AE25="",AF25=""),"",INDEX(RiskGrid,6-VALUE(LEFT(AE25,1)),VALUE(LEFT(AF25,1)))) | AH25: =IF(AG25="","",IF(AG25>=BandVH,"Very High",IF(AG25>=BandHigh,"High",IF(AG25>=BandMed,"Medium","Low"))))
A26: =IF(B26="","",COUNTIF(B$14:B26,"?*")) | D26: =IF(OR(B26="",C26=""),"",UPPER(LEFT(C26,1))&LOWER(MID(C26,2,30))&" "&LOWER(LEFT(B26,1))&MID(B26,2,200)) | K26: =_xlfn.TEXTJOIN(CHAR(10),TRUE,IF(E26="","","• "&E26),IF(F26="","","• "&F26),IF(G26="","","• "&G26),IF(H26="","","• "&H26),IF(I26="","","• "&I26),IF(J26="","","• "&J26)) | O26: =IF(OR(M26="",N26=""),"",INDEX(RiskGrid,6-VALUE(LEFT(M26,1)),VALUE(LEFT(N26,1)))) | P26: =IF(O26="","",IF(O26>=BandVH,"Very High",IF(O26>=BandHigh,"High",IF(O26>=BandMed,"Medium","Low")))) | AC26: =_xlfn.TEXTJOIN(CHAR(10),TRUE,IF(Q26="","","• "&Q26&IF(R26="Yes"," [IPL]","")),IF(S26="","","• "&S26&IF(T26="Yes"," [IPL]","")),IF(U26="","","• "&U26&IF(V26="Yes"," [IPL]","")),IF(W26="","","• "&W26&IF(X26="Yes"," [IPL]","")),IF(Y26="","","• "&Y26&IF(Z26="Yes"," [IPL]","")),IF(AA26="","","• "&AA26&IF(AB26="Yes"," [IPL]",""))) | AD26: =IF(AC26="","",COUNTIF(Q26:AB26,"Yes")) | AG26: =IF(OR(AE26="",AF26=""),"",INDEX(RiskGrid,6-VALUE(LEFT(AE26,1)),VALUE(LEFT(AF26,1)))) | AH26: =IF(AG26="","",IF(AG26>=BandVH,"Very High",IF(AG26>=BandHigh,"High",IF(AG26>=BandMed,"Medium","Low"))))
A27: =IF(B27="","",COUNTIF(B$14:B27,"?*")) | D27: =IF(OR(B27="",C27=""),"",UPPER(LEFT(C27,1))&LOWER(MID(C27,2,30))&" "&LOWER(LEFT(B27,1))&MID(B27,2,200)) | K27: =_xlfn.TEXTJOIN(CHAR(10),TRUE,IF(E27="","","• "&E27),IF(F27="","","• "&F27),IF(G27="","","• "&G27),IF(H27="","","• "&H27),IF(I27="","","• "&I27),IF(J27="","","• "&J27)) | O27: =IF(OR(M27="",N27=""),"",INDEX(RiskGrid,6-VALUE(LEFT(M27,1)),VALUE(LEFT(N27,1)))) | P27: =IF(O27="","",IF(O27>=BandVH,"Very High",IF(O27>=BandHigh,"High",IF(O27>=BandMed,"Medium","Low")))) | AC27: =_xlfn.TEXTJOIN(CHAR(10),TRUE,IF(Q27="","","• "&Q27&IF(R27="Yes"," [IPL]","")),IF(S27="","","• "&S27&IF(T27="Yes"," [IPL]","")),IF(U27="","","• "&U27&IF(V27="Yes"," [IPL]","")),IF(W27="","","• "&W27&IF(X27="Yes"," [IPL]","")),IF(Y27="","","• "&Y27&IF(Z27="Yes"," [IPL]","")),IF(AA27="","","• "&AA27&IF(AB27="Yes"," [IPL]",""))) | AD27: =IF(AC27="","",COUNTIF(Q27:AB27,"Yes")) | AG27: =IF(OR(AE27="",AF27=""),"",INDEX(RiskGrid,6-VALUE(LEFT(AE27,1)),VALUE(LEFT(AF27,1)))) | AH27: =IF(AG27="","",IF(AG27>=BandVH,"Very High",IF(AG27>=BandHigh,"High",IF(AG27>=BandMed,"Medium","Low"))))
A28: =IF(B28="","",COUNTIF(B$14:B28,"?*")) | D28: =IF(OR(B28="",C28=""),"",UPPER(LEFT(C28,1))&LOWER(MID(C28,2,30))&" "&LOWER(LEFT(B28,1))&MID(B28,2,200)) | K28: =_xlfn.TEXTJOIN(CHAR(10),TRUE,IF(E28="","","• "&E28),IF(F28="","","• "&F28),IF(G28="","","• "&G28),IF(H28="","","• "&H28),IF(I28="","","• "&I28),IF(J28="","","• "&J28)) | O28: =IF(OR(M28="",N28=""),"",INDEX(RiskGrid,6-VALUE(LEFT(M28,1)),VALUE(LEFT(N28,1)))) | P28: =IF(O28="","",IF(O28>=BandVH,"Very High",IF(O28>=BandHigh,"High",IF(O28>=BandMed,"Medium","Low")))) | AC28: =_xlfn.TEXTJOIN(CHAR(10),TRUE,IF(Q28="","","• "&Q28&IF(R28="Yes"," [IPL]","")),IF(S28="","","• "&S28&IF(T28="Yes"," [IPL]","")),IF(U28="","","• "&U28&IF(V28="Yes"," [IPL]","")),IF(W28="","","• "&W28&IF(X28="Yes"," [IPL]","")),IF(Y28="","","• "&Y28&IF(Z28="Yes"," [IPL]","")),IF(AA28="","","• "&AA28&IF(AB28="Yes"," [IPL]",""))) | AD28: =IF(AC28="","",COUNTIF(Q28:AB28,"Yes")) | AG28: =IF(OR(AE28="",AF28=""),"",INDEX(RiskGrid,6-VALUE(LEFT(AE28,1)),VALUE(LEFT(AF28,1)))) | AH28: =IF(AG28="","",IF(AG28>=BandVH,"Very High",IF(AG28>=BandHigh,"High",IF(AG28>=BandMed,"Medium","Low"))))
A29: =IF(B29="","",COUNTIF(B$14:B29,"?*")) | D29: =IF(OR(B29="",C29=""),"",UPPER(LEFT(C29,1))&LOWER(MID(C29,2,30))&" "&LOWER(LEFT(B29,1))&MID(B29,2,200)) | K29: =_xlfn.TEXTJOIN(CHAR(10),TRUE,IF(E29="","","• "&E29),IF(F29="","","• "&F29),IF(G29="","","• "&G29),IF(H29="","","• "&H29),IF(I29="","","• "&I29),IF(J29="","","• "&J29)) | O29: =IF(OR(M29="",N29=""),"",INDEX(RiskGrid,6-VALUE(LEFT(M29,1)),VALUE(LEFT(N29,1)))) | P29: =IF(O29="","",IF(O29>=BandVH,"Very High",IF(O29>=BandHigh,"High",IF(O29>=BandMed,"Medium","Low")))) | AC29: =_xlfn.TEXTJOIN(CHAR(10),TRUE,IF(Q29="","","• "&Q29&IF(R29="Yes"," [IPL]","")),IF(S29="","","• "&S29&IF(T29="Yes"," [IPL]","")),IF(U29="","","• "&U29&IF(V29="Yes"," [IPL]","")),IF(W29="","","• "&W29&IF(X29="Yes"," [IPL]","")),IF(Y29="","","• "&Y29&IF(Z29="Yes"," [IPL]","")),IF(AA29="","","• "&AA29&IF(AB29="Yes"," [IPL]",""))) | AD29: =IF(AC29="","",COUNTIF(Q29:AB29,"Yes")) | AG29: =IF(OR(AE29="",AF29=""),"",INDEX(RiskGrid,6-VALUE(LEFT(AE29,1)),VALUE(LEFT(AF29,1)))) | AH29: =IF(AG29="","",IF(AG29>=BandVH,"Very High",IF(AG29>=BandHigh,"High",IF(AG29>=BandMed,"Medium","Low"))))
A30: =IF(B30="","",COUNTIF(B$14:B30,"?*")) | D30: =IF(OR(B30="",C30=""),"",UPPER(LEFT(C30,1))&LOWER(MID(C30,2,30))&" "&LOWER(LEFT(B30,1))&MID(B30,2,200)) | K30: =_xlfn.TEXTJOIN(CHAR(10),TRUE,IF(E30="","","• "&E30),IF(F30="","","• "&F30),IF(G30="","","• "&G30),IF(H30="","","• "&H30),IF(I30="","","• "&I30),IF(J30="","","• "&J30)) | O30: =IF(OR(M30="",N30=""),"",INDEX(RiskGrid,6-VALUE(LEFT(M30,1)),VALUE(LEFT(N30,1)))) | P30: =IF(O30="","",IF(O30>=BandVH,"Very High",IF(O30>=BandHigh,"High",IF(O30>=BandMed,"Medium","Low")))) | AC30: =_xlfn.TEXTJOIN(CHAR(10),TRUE,IF(Q30="","","• "&Q30&IF(R30="Yes"," [IPL]","")),IF(S30="","","• "&S30&IF(T30="Yes"," [IPL]","")),IF(U30="","","• "&U30&IF(V30="Yes"," [IPL]","")),IF(W30="","","• "&W30&IF(X30="Yes"," [IPL]","")),IF(Y30="","","• "&Y30&IF(Z30="Yes"," [IPL]","")),IF(AA30="","","• "&AA30&IF(AB30="Yes"," [IPL]",""))) | AD30: =IF(AC30="","",COUNTIF(Q30:AB30,"Yes")) | AG30: =IF(OR(AE30="",AF30=""),"",INDEX(RiskGrid,6-VALUE(LEFT(AE30,1)),VALUE(LEFT(AF30,1)))) | AH30: =IF(AG30="","",IF(AG30>=BandVH,"Very High",IF(AG30>=BandHigh,"High",IF(AG30>=BandMed,"Medium","Low"))))
A31: =IF(B31="","",COUNTIF(B$14:B31,"?*")) | D31: =IF(OR(B31="",C31=""),"",UPPER(LEFT(C31,1))&LOWER(MID(C31,2,30))&" "&LOWER(LEFT(B31,1))&MID(B31,2,200)) | K31: =_xlfn.TEXTJOIN(CHAR(10),TRUE,IF(E31="","","• "&E31),IF(F31="","","• "&F31),IF(G31="","","• "&G31),IF(H31="","","• "&H31),IF(I31="","","• "&I31),IF(J31="","","• "&J31)) | O31: =IF(OR(M31="",N31=""),"",INDEX(RiskGrid,6-VALUE(LEFT(M31,1)),VALUE(LEFT(N31,1)))) | P31: =IF(O31="","",IF(O31>=BandVH,"Very High",IF(O31>=BandHigh,"High",IF(O31>=BandMed,"Medium","Low")))) | AC31: =_xlfn.TEXTJOIN(CHAR(10),TRUE,IF(Q31="","","• "&Q31&IF(R31="Yes"," [IPL]","")),IF(S31="","","• "&S31&IF(T31="Yes"," [IPL]","")),IF(U31="","","• "&U31&IF(V31="Yes"," [IPL]","")),IF(W31="","","• "&W31&IF(X31="Yes"," [IPL]","")),IF(Y31="","","• "&Y31&IF(Z31="Yes"," [IPL]","")),IF(AA31="","","• "&AA31&IF(AB31="Yes"," [IPL]",""))) | AD31: =IF(AC31="","",COUNTIF(Q31:AB31,"Yes")) | AG31: =IF(OR(AE31="",AF31=""),"",INDEX(RiskGrid,6-VALUE(LEFT(AE31,1)),VALUE(LEFT(AF31,1)))) | AH31: =IF(AG31="","",IF(AG31>=BandVH,"Very High",IF(AG31>=BandHigh,"High",IF(AG31>=BandMed,"Medium","Low"))))
A32: =IF(B32="","",COUNTIF(B$14:B32,"?*")) | D32: =IF(OR(B32="",C32=""),"",UPPER(LEFT(C32,1))&LOWER(MID(C32,2,30))&" "&LOWER(LEFT(B32,1))&MID(B32,2,200)) | K32: =_xlfn.TEXTJOIN(CHAR(10),TRUE,IF(E32="","","• "&E32),IF(F32="","","• "&F32),IF(G32="","","• "&G32),IF(H32="","","• "&H32),IF(I32="","","• "&I32),IF(J32="","","• "&J32)) | O32: =IF(OR(M32="",N32=""),"",INDEX(RiskGrid,6-VALUE(LEFT(M32,1)),VALUE(LEFT(N32,1)))) | P32: =IF(O32="","",IF(O32>=BandVH,"Very High",IF(O32>=BandHigh,"High",IF(O32>=BandMed,"Medium","Low")))) | AC32: =_xlfn.TEXTJOIN(CHAR(10),TRUE,IF(Q32="","","• "&Q32&IF(R32="Yes"," [IPL]","")),IF(S32="","","• "&S32&IF(T32="Yes"," [IPL]","")),IF(U32="","","• "&U32&IF(V32="Yes"," [IPL]","")),IF(W32="","","• "&W32&IF(X32="Yes"," [IPL]","")),IF(Y32="","","• "&Y32&IF(Z32="Yes"," [IPL]","")),IF(AA32="","","• "&AA32&IF(AB32="Yes"," [IPL]",""))) | AD32: =IF(AC32="","",COUNTIF(Q32:AB32,"Yes")) | AG32: =IF(OR(AE32="",AF32=""),"",INDEX(RiskGrid,6-VALUE(LEFT(AE32,1)),VALUE(LEFT(AF32,1)))) | AH32: =IF(AG32="","",IF(AG32>=BandVH,"Very High",IF(AG32>=BandHigh,"High",IF(AG32>=BandMed,"Medium","Low"))))
... A113: =IF(B113="","",COUNTIF(B$14:B113,"?*")) | D113: =IF(OR(B113="",C113=""),"",UPPER(LEFT(C113,1))&LOWER(MID(C113,2,30))&" "&LOWER(LEFT(B113,1))&MID(B113,2,200)) | K113: =_xlfn.TEXTJOIN(CHAR(10),TRUE,IF(E113="","","• "&E113),IF(F113="","","• "&F113),IF(G113="","","• "&G113),IF(H113="","","• "&H113),IF(I113="","","• "&I113),IF(J113="","","• "&J113)) | O113: =IF(OR(M113="",N113=""),"",INDEX(RiskGrid,6-VALUE(LEFT(M113,1)),VALUE(LEFT(N113,1)))) | P113: =IF(O113="","",IF(O113>=BandVH,"Very High",IF(O113>=BandHigh,"High",IF(O113>=BandMed,"Medium","Low")))) | AC113: =_xlfn.TEXTJOIN(CHAR(10),TRUE,IF(Q113="","","• "&Q113&IF(R113="Yes"," [IPL]","")),IF(S113="","","• "&S113&IF(T113="Yes"," [IPL]","")),IF(U113="","","• "&U113&IF(V113="Yes"," [IPL]","")),IF(W113="","","• "&W113&IF(X113="Yes"," [IPL]","")),IF(Y113="","","• "&Y113&IF(Z113="Yes"," [IPL]","")),IF(AA113="","","• "&AA113&IF(AB113="Yes"," [IPL]",""))) | AD113: =IF(AC113="","",COUNTIF(Q113:AB113,"Yes")) | AG113: =IF(OR(AE113="",AF113=""),"",INDEX(RiskGrid,6-VALUE(LEFT(AE113,1)),VALUE(LEFT(AF113,1)))) | AH113: =IF(AG113="","",IF(AG113>=BandVH,"Very High",IF(AG113>=BandHigh,"High",IF(AG113>=BandMed,"Medium","Low"))))

Sheet Node 02
A1: HAZOP WORKSHEET | E1: =Cover!B7
A3: Select node ▸ | D3: N02 – Gas heaters H-1101A/B and pressure reduction station PRS-1 | M3: Session date | N3: 46307 | P3: Revision | Q3: A
A4: Node title | D4: =IF($D$3="","",IFERROR(INDEX(Nodes!$B$5:$B$34,MATCH($D$3,Nodes!$C$5:$C$34,0))&"",""))
A5: P&IDs / drawings | D5: =IF($D$3="","",IFERROR(INDEX(Nodes!$D$5:$D$34,MATCH($D$3,Nodes!$C$5:$C$34,0))&"",""))
A6: Battery limits | D6: =IF($D$3="","",IFERROR(INDEX(Nodes!$E$5:$E$34,MATCH($D$3,Nodes!$C$5:$C$34,0))&"",""))
A7: Functional description / design intent | D7: =IF($D$3="","",IFERROR(INDEX(Nodes!$F$5:$F$34,MATCH($D$3,Nodes!$C$5:$C$34,0))&"",""))
A8: Design parameters | D8: =IF($D$3="","",IFERROR(INDEX(Nodes!$G$5:$G$34,MATCH($D$3,Nodes!$C$5:$C$34,0))&"",""))
A9: Operating parameters | D9: =IF($D$3="","",IFERROR(INDEX(Nodes!$H$5:$H$34,MATCH($D$3,Nodes!$C$5:$C$34,0))&"",""))
A11: ONE ROW PER DEVIATION. Choose Parameter + Guideword, then pick up to 6 causes in Cause 1–6 (or type your own) – they are listed line by line in 'Potential causes'. Enter up to 6 safeguards, each marked IPL Yes/No – listed in 'Safeguards'. Use the [–] buttons above the columns to collapse the pick columns.
A12: DEVIATION | E12: CAUSE PICK-LIST | K12: CAUSES & CONSEQUENCES | M12: RISK BEFORE SAFEGUARDS | Q12: SAFEGUARD ENTRY (mark each IPL Yes / No) | AC12: SAFEGUARDS | AE12: RISK AFTER SAFEGUARDS | AI12: RECOMMENDATIONS
A13: Dev. No. | B13: Parameter | C13: Guideword | D13: Deviation | E13: Cause 1 | F13: Cause 2 | G13: Cause 3 | H13: Cause 4 | I13: Cause 5 | J13: Cause 6 | K13: Potential causes | L13: Consequences | M13: Severity (S) | N13: Likelihood (L) | O13: Risk score | P13: Risk rank | Q13: Safeguard 1 | R13: IPL? 1 | S13: Safeguard 2 | T13: IPL? 2 | U13: Safeguard 3 | V13: IPL? 3 | W13: Safeguard 4 | X13: IPL? 4 | Y13: Safeguard 5 | Z13: IPL? 5 | AA13: Safeguard 6 | AB13: IPL? 6 | AC13: Safeguards | AD13: No. of IPLs | AE13: Severity (S) | AF13: Likelihood (L) | AG13: Risk score | AH13: Risk rank | AI13: Recommendations / actions | AJ13: Action by
