Workbook
Name SystemList: Systems!$C$5:$C$34
Name EqSys: 'Equipment Register'!$B$5:$B$204
Name EqTag: 'Equipment Register'!$C$5:$C$204
Name EqTypeCol: 'Equipment Register'!$E$5:$E$204
Name EqTypeList: Lists!$A$5:$A$33
Name CompType: Lists!$C$5:$C$329
Name CompStart: Lists!$D$5
Name FMType: Lists!$F$5:$F$353
Name FMStart: Lists!$G$5
Name MechList: Lists!$I$5:$I$62
Name DetList: Lists!$K$5:$K$25
Name TaskList: Lists!$M$5:$M$13
Name DocCategories: Lists!$O$5:$O$11
Name SevList: 'Rating Scales'!$B$5:$B$14
Name OccList: 'Rating Scales'!$B$17:$B$26
Name DetScaleList: 'Rating Scales'!$B$29:$B$38
Name SThr: 'Rating Scales'!$C$41
Name RPNThr: 'Rating Scales'!$C$42
Name APGrid: 'Rating Scales'!$E$50:$H$74
Name APS: 'Rating Scales'!$E$77:$I$77
Name APO: 'Rating Scales'!$E$78:$I$78
Name APD: 'Rating Scales'!$E$79:$H$79

Sheet Cover
A1: FMECA WORKBOOK
A2: Failure Modes, Effects and Criticality Analysis – companion to the HAZOP Study Workbook (IEC 60812 approach)
A4: Legend: | B4: Yellow = enter / select data | C4: Grey = formula (do not overwrite) | D4: Blue = returned from another sheet
A6: STUDY DETAILS
A7: Study title | B7: FMECA – Natural gas distribution network (worked example)
A8: Company / site | B8: Hadeed – integrated DRI-EAF steel works (illustrative example)
A9: Plant / unit / area | B9: Utilities – natural gas receiving, pressure reduction and plant distribution
A10: Related HAZOP study (document no.) | B10: HZ-EX-GN-001
A11: Study type | B11: FMECA – existing plant
A12: Document number | B12: FM-EX-GN-001
A13: Revision | B13: A
A14: Study start date | B14: 2026-10-15
A15: Study end date | B15: 2026-10-16
A16: Scope – systems included | B16: S01–S08 = HAZOP nodes N01–N08: GRMS, heaters + PRS-1, MP ring main, DS-2 (DRI), DS-3 (melt shop), reheat furnace fuel train + BMS, purge / vent, gas detection & ESD
A17: Exclusions | B17: As the HAZOP (supplier pipeline, reformer internals, O2 plant, N2 generation)
A18: Level of analysis | B18: Equipment / maintainable item
... A22: Rating method | B22: Severity, Occurrence, Detection 1–10; RPN = S x O x D; AIAG-VDA Action Priority (see 'Rating Scales')
A23: Number of systems | B23: =COUNTA(Systems!B5:B34)
A24: Number of equipment items | B24: =COUNTA('Equipment Register'!C5:C204)
A26: STUDY TEAM
A27: Name | B27: Company | C27: Discipline / role | D27: Sessions / days attended | E27: Signature
A28: A. Facilitator | B28: Istec | C28: Facilitator | D28: Days 1–2
A29: B. Scribe | B29: Istec | C29: Scribe | D29: Days 1–2
A30: E. Instrument | B30: Maintenance | C30: Electrical / instrument technician | D30: Days 1–2
A31: F. Mechanical | B31: Maintenance | C31: Maintenance engineer / planner | D31: Days 1–2
A32: J. Reliability | B32: Maintenance | C32: Reliability engineer | D32: Days 1–2
A33: D. Operator | B33: Utilities | C33: Operations representative | D33: Days 1–2
A41: APPROVAL
B42: Name | C42: Position | D42: Signature | E42: Date
A43: Prepared by
A44: Reviewed by
A45: Approved by
A47: WORKBOOK CONTENTS
A48: Cover | B48: Study details, team, approval
A49: Reference Docs | B49: Drawings, equipment data, maintenance history and reliability data used in the study
A50: Systems | B50: System list: function, operating context, boundaries, drawings, related HAZOP nodes
A51: Equipment Register | B51: Equipment tags per system with equipment type (drives the drop-downs on the system sheets)
A52: Lists | B52: Drop-down sources: equipment types, components, failure modes, causes / mechanisms, detection methods (editable)
A53: Rating Scales | B53: Severity, Occurrence, Detection 1–10 scales, RPN / severity thresholds and Action Priority table (editable)
A54: Summary | B54: Failure modes, Action Priority counts, highest RPN and open actions per system
...

Sheet Reference Docs
A1: REFERENCE DOCUMENT REGISTER
A2: Pre-filled with a typical FMECA checklist – delete or add rows as required.
A4: Ref | B4: Category | C4: Document number | D4: Title / description | E4: Revision | F4: Date | G4: Owner / custodian | H4: Status | I4: Applicable systems | J4: Comments
A5: REF-01 | B5: Drawings | C5: P&ID-GN-1001 | D5: Gas receiving & metering station (GRMS) P&ID | E5: A | G5: Utilities | H5: Available | I5: S01
A6: REF-02 | B6: Drawings | C6: P&ID-GN-1101 | D6: Gas heaters and pressure reduction station PRS-1 P&ID | E6: A | G6: Utilities | H6: Available | I6: S02
A7: REF-03 | B7: Drawings | C7: P&ID-GN-1201/1202 | D7: MP ring main and pipe-rack routing | E7: A | G7: Utilities | H7: Available | I7: S03
A8: REF-04 | B8: Drawings | C8: P&ID-GN-2001 | D8: DRI plant district station DS-2 | E8: A | G8: Utilities | H8: Available | I8: S04
A9: REF-05 | B9: Drawings | C9: P&ID-GN-3001 | D9: Melt shop district station DS-3, oxy-fuel burners and ladle preheaters | E9: A | G9: Utilities | H9: Available | I9: S05
A10: REF-06 | B10: Drawings | C10: P&ID-GN-4001 | D10: Rolling-mill reheat furnace fuel gas train and BMS | E10: A | G10: Utilities | H10: Available | I10: S06
A11: REF-07 | B11: Drawings | C11: P&ID-GN-1301 | D11: Vent stack, blowdown and N2 purge connections | E11: A | G11: Utilities | H11: Available | I11: S07
A12: REF-08 | B12: Drawings | C12: C&E-GN-1000 | D12: ESD / F&G cause-and-effect charts | E12: A | G12: Utilities | H12: Available | I12: S01, S02, S08
A13: REF-09 | B13: Drawings | C13: HAC-GN-001 | D13: Hazardous area classification – gas network | E13: A | G13: Utilities | H13: Available | I13: S01, S02, S03, S07
A14: REF-10 | B14: Other | C14: DB-GN-001 | D14: Gas network design basis (pressures, set points, MDMT) | E14: A | G14: Utilities | H14: Available | I14: S01, S02, S03
A15: REF-11 | B15: Other | C15: RS-GN-001 | D15: Relief and overpressure protection study | E15: A | G15: Utilities | H15: Available | I15: S01, S02, S07
A16: REF-12 | B16: Other | C16: SRS-GN-001 | D16: Safety requirements specification – gas ESD and furnace BMS | E16: A | G16: Utilities | H16: Available | I16: S06, S08
... A24: REF-20 | B24: Other | C24: FT-GN-01/02/03 | D24: Fault trees – PRS overpressure, gas detection & ESD, reheat furnace BMS | E24: A | G24: Utilities | H24: Available | I24: S02, S08, S06
A25: REF-21 | B25: Other | C25: OREDA / CCPS | D25: Generic reliability data used for the illustrative failure rates | E25: A | G25: Utilities | H25: Available
A26: REF-22
A27: REF-23
A28: REF-24
A29: REF-25
A30: REF-26
A31: REF-27
A32: REF-28
A33: REF-29
A34: REF-30
A35: REF-31
A36: REF-32
A37: REF-33
... A44: REF-40

Sheet Systems
A1: SYSTEM LIST
A2: One row per system. System title (column C) feeds the drop-down at the top of each FMECA worksheet and the Equipment Register.
A4: System No. | B4: System name | C4: System title (auto) | D4: Function / performance standard | E4: Operating context (duty, redundancy, environment) | F4: System boundaries | G4: P&IDs / drawings | H4: Related HAZOP node(s) | I4: Comments
A5: S01 | B5: Gas receiving & metering station (GRMS) | C5: =IF(B5="","",A5&" – "&B5) | D5: Receive, filter and meter up to 120 000 Sm3/h at 35–42 barg; isolate on ESD within 30 s | E5: Continuous; 2 x 100 % filter-separators and meter runs; outdoor, hot / dusty | F5: IJ-1001 to heater inlet | G5: P&ID-GN-1001 | H5: HAZOP N01
A6: S02 | B6: Gas heaters H-1101A/B and pressure reduction station PRS-1 | C6: =IF(B6="","",A6&" – "&B6) | D6: Heat gas to keep outlet ≥ 5 °C; hold 7.0 barg; never exceed 10 barg downstream | E6: Continuous; 2 x 100 % heaters and regulator runs (A duty, B standby); monitor + slam-shut protection proof-tested | F6: Heater inlet to ESDV-1107 | G6: P&ID-GN-1101 | H6: HAZOP N02
A7: S03 | B7: MP ring main (7 barg) and pipe racks | C7: =IF(B7="","",A7&" – "&B7) | D7: Distribute 7 barg gas without loss of containment | E7: Continuous; buried crossings with impressed-current CP; racks crossing roads and crane areas | F7: ESDV-1107 to district-station inlets | G7: P&ID-GN-1201/1202 | H7: HAZOP N03
A8: S04 | B8: DRI plant gas supply – district station DS-2 | C8: =IF(B8="","",A8&" – "&B8) | D8: Supply reformer fuel and process-gas make-up at 4.5 barg; prevent reverse flow of process gas | E8: Continuous; 2 x 100 % regulators | F8: ESDV-2001 to FCV-2004 / XV-2008 | G8: P&ID-GN-2001 | H8: HAZOP N04
A9: S05 | B9: Melt shop gas supply – DS-3, EAF oxy-fuel burners and ladle preheaters | C9: =IF(B9="","",A9&" – "&B9) | D9: Supply NG at 2 barg; prevent O2 back-flow; shut off on flame failure | E9: Intermittent; hot, dusty, molten-metal splash zone | F9: ESDV-3001 to burners | G9: P&ID-GN-3001 | H9: HAZOP N05
A10: S06 | B10: Rolling-mill reheat furnace fuel gas train and burner management | C10: =IF(B10="","",A10&" – "&B10) | D10: Fire only when safe; shut off fuel within 1 s on flame failure (target SIL 2 – see R-010) | E10: Continuous firing with cold light-offs after outages; BMS proof-tested annually | F10: PCV-4001 to burners B-4020 | G10: P&ID-GN-4001 | H10: HAZOP N06
A11: S07 | B11: Purge, vent, blowdown and maintenance isolation | C11: =IF(B11="","",A11&" – "&B11) | D11: Depressurise, purge and isolate safely | E11: Used during maintenance, pigging and gas-in / gas-out | F11: VS-1301, BDV-1302, SB-1303, N2-1304 | G11: P&ID-GN-1301 | H11: HAZOP N07
A12: S08 | B12: Gas detection, F&G and ESD system | C12: =IF(B12="","",A12&" – "&B12) | D12: Detect a release and close ESDV-1001 / ESDV-1107 (PFDavg per FT-GN-02) | E12: Standby protection; 2oo3 detectors; UPS 30 min; proof-tested | F12: Detectors, HS-1000, UCP-1000, UPS-1000 | G12: C&E-GN-1000 | H12: HAZOP N08
A13: S09 | C13: =IF(B13="","",A13&" – "&B13)
A14: S10 | C14: =IF(B14="","",A14&" – "&B14)
A15: S11 | C15: =IF(B15="","",A15&" – "&B15)
A16: S12 | C16: =IF(B16="","",A16&" – "&B16)
A17: S13 | C17: =IF(B17="","",A17&" – "&B17)
A18: S14 | C18: =IF(B18="","",A18&" – "&B18)
A19: S15 | C19: =IF(B19="","",A19&" – "&B19)
A20: S16 | C20: =IF(B20="","",A20&" – "&B20)
A21: S17 | C21: =IF(B21="","",A21&" – "&B21)
A22: S18 | C22: =IF(B22="","",A22&" – "&B22)
A23: S19 | C23: =IF(B23="","",A23&" – "&B23)
A24: S20 | C24: =IF(B24="","",A24&" – "&B24)
... A34: S30 | C34: =IF(B34="","",A34&" – "&B34)

Sheet Equipment Register
A1: EQUIPMENT REGISTER
A2: List every equipment item in scope against its system. Equipment type selects the component and failure-mode lists on the FMECA sheets.
A4: Item | B4: System | C4: Equipment tag | D4: Equipment description | E4: Equipment type | F4: Manufacturer / model | G4: Configuration | H4: Function | I4: Comments
A5: 1 | B5: S01 – Gas receiving & metering station (GRMS) | C5: IJ-1001 | D5: Inlet insulating joint and buried inlet piping | E5: Piping, flanges & hoses | G5: Single | H5: Electrically isolate the plant from the supplier pipeline CP
A6: 2 | B6: S01 – Gas receiving & metering station (GRMS) | C6: ESDV-1001 | D6: GRMS inlet ESD valve | E6: Isolation / ESD valve | G6: Single | H6: Isolate the supplier pipeline on ESD (fail closed)
A7: 3 | B7: S01 – Gas receiving & metering station (GRMS) | C7: PR-1001 | D7: Pig receiver with quick-opening closure | E7: Pressure vessel / separator / column | G7: Single | H7: Receive pigs from the supplier pipeline
A8: 4 | B8: S01 – Gas receiving & metering station (GRMS) | C8: F-1002A | D8: Filter-separator A | E8: Pressure vessel / separator / column | G8: Duty | H8: Remove liquids and solids
A9: 5 | B9: S01 – Gas receiving & metering station (GRMS) | C9: F-1002B | D9: Filter-separator B | E9: Pressure vessel / separator / column | G9: Standby | H9: Remove liquids and solids
A10: 6 | B10: S01 – Gas receiving & metering station (GRMS) | C10: FT-1003A | D10: Ultrasonic custody meter A | E10: Instrument – transmitter / switch | G10: Duty | H10: Custody-transfer metering
A11: 7 | B11: S01 – Gas receiving & metering station (GRMS) | C11: AT-1004 | D11: Gas chromatograph | E11: Analyser / gas detector | G11: Single | H11: Composition, Wobbe and H2S
A12: 8 | B12: S01 – Gas receiving & metering station (GRMS) | C12: PSV-1006A | D12: Filter-separator A relief valve | E12: Pressure relief device (PSV / rupture disc) | G12: Single | H12: Fire-case / thermal relief
A13: 9 | B13: S02 – Gas heaters H-1101A/B and pressure reduction station PRS-1 | C13: H-1101A | D13: Water-bath gas heater A | E13: Burner / combustion system | G13: Duty | H13: Pre-heat gas against Joule–Thomson cooling
A14: 10 | B14: S02 – Gas heaters H-1101A/B and pressure reduction station PRS-1 | C14: H-1101B | D14: Water-bath gas heater B | E14: Burner / combustion system | G14: Standby | H14: Pre-heat gas against Joule–Thomson cooling
A15: 11 | B15: S02 – Gas heaters H-1101A/B and pressure reduction station PRS-1 | C15: TT-1101 | D15: Heater gas outlet temperature transmitter | E15: Instrument – transmitter / switch | G15: Single | H15: TIC-1101 control and TSL-1101 alarm
A16: 12 | B16: S02 – Gas heaters H-1101A/B and pressure reduction station PRS-1 | C16: SSV-1102A | D16: Slam-shut valve run A (OPSO 8.5 barg) | E16: Isolation / ESD valve | G16: Duty | H16: Close run A on overpressure
... A52: 48 | B52: S08 – Gas detection, F&G and ESD system | C52: UPS-1000 | D52: UPS for SIS / F&G | E52: Variable speed drive / UPS | G52: Single | H52: 30 min back-up power
A53: 49
A54: 50
A55: 51
A56: 52
A57: 53
A58: 54
A59: 55
A60: 56
A61: 57
A62: 58
A63: 59
A64: 60
... A204: 200

Sheet Lists
A1: DROP-DOWN LISTS
A2: Editable. To add a component or failure mode, INSERT a row inside its equipment-type block (blocks must stay together). Failure-mode codes follow ISO 14224 where applicable.
A4: Equipment types | C4: Equipment type | D4: Component / maintainable item | F4: Equipment type | G4: Failure mode | I4: Failure causes / mechanisms | K4: Detection methods | M4: Action / task type | O4: Document category
A5: Centrifugal pump | C5: Centrifugal pump | D5: Impeller | F5: Centrifugal pump | G5: FTS – Fail to start on demand | I5: 1.0 Mechanical failure – general | K5: Online vibration monitoring with alarm | M5: Condition monitoring task | O5: Drawings
A6: Positive displacement pump | C6: Centrifugal pump | D6: Casing | F6: Centrifugal pump | G6: STP – Fail to stop on demand | I6: 1.1 Leakage | K6: Periodic vibration analysis (route) | M6: Time-based maintenance / overhaul | O6: Equipment data
A7: Centrifugal compressor | C7: Centrifugal pump | D7: Shaft | F7: Centrifugal pump | G7: UST – Spurious stop | I7: 1.2 Vibration | K7: Infrared thermography | M7: Failure-finding / proof test | O7: Maintenance history
A8: Reciprocating compressor | C8: Centrifugal pump | D8: Bearings | F8: Centrifugal pump | G8: BRD – Breakdown | I8: 1.3 Clearance / alignment failure | K8: Oil / lubricant analysis | M8: Operator round / inspection | O8: Reliability data
A9: Fan / blower (incl. ID fan) | C9: Centrifugal pump | D9: Mechanical seal | F9: Centrifugal pump | G9: LOO – Low output (flow / head) | I9: 1.4 Deformation | K9: Ultrasonic thickness / NDT inspection | M9: Redesign / modification (MOC) | O9: Procedures
A10: Electric motor | C10: Centrifugal pump | D10: Coupling | F10: Centrifugal pump | G10: HIO – High output | I10: 1.5 Looseness | K10: Acoustic emission / ultrasonic leak detection | M10: Spares holding | O10: Previous studies
A11: Gearbox | C11: Centrifugal pump | D11: Wear rings | F11: Centrifugal pump | G11: ELP – External leakage – process medium | I11: 1.6 Sticking / seizure | K11: Motor current signature analysis | M11: Procedure / training | O11: Other
A12: Belt conveyor | C12: Centrifugal pump | D12: Baseplate / holding-down | F12: Centrifugal pump | G12: ELU – External leakage – utility medium | I12: 2.0 Material failure – general | K12: Partial discharge / insulation testing | M12: Run to failure (accepted)
A13: Pressure vessel / separator / column | C13: Centrifugal pump | D13: Lubrication system | F13: Centrifugal pump | G13: INL – Internal leakage / recirculation | I13: 2.1 Cavitation | K13: Process alarm (DCS) | M13: Further study
A14: Shell & tube heat exchanger | C14: Centrifugal pump | D14: Suction strainer | F14: Centrifugal pump | G14: VIB – Vibration | I14: 2.2 Corrosion (general / pitting / CUI) | K14: Protective trip / interlock
A15: Atmospheric storage tank | C15: Positive displacement pump | D15: Rotors / gears / pistons | F15: Centrifugal pump | G15: NOI – Noise | I15: 2.3 Erosion | K15: Performance monitoring (flow, ΔP, efficiency)
A16: Piping, flanges & hoses | C16: Positive displacement pump | D16: Suction / discharge valves | F16: Centrifugal pump | G16: OHE – Overheating | I16: 2.4 Wear | K16: Operator rounds – visual / sensory
A17: Control valve | C17: Positive displacement pump | D17: Packing / seals | F17: Centrifugal pump | G17: PDE – Parameter deviation | I17: 2.5 Breakage / fracture | K17: Proof test / function test
A18: Isolation / ESD valve | C18: Positive displacement pump | D18: Bearings | F18: Centrifugal pump | G18: STD – Structural deficiency | I18: 2.6 Fatigue (mechanical / thermal) | K18: Leak detection system (flow in / out)
A19: Pressure relief device (PSV / rupture disc) | C19: Positive displacement pump | D19: Drive (gearbox / coupling) | F19: Centrifugal pump | G19: PLU – Plugged / choked | I19: 2.7 Overheating | K19: Gas / fire detection
A20: Instrument – transmitter / switch | C20: Positive displacement pump | D20: Pulsation damper | F20: Centrifugal pump | G20: OTH – Other | I20: 2.8 Burst | K20: Shell temperature scanning (refractory)
A21: Analyser / gas detector | C21: Positive displacement pump | D21: Integral relief valve | F21: Positive displacement pump | G21: FTS – Fail to start on demand | I21: 3.0 Instrument failure – general | K21: Rope / brake / structural inspection (cranes)
A22: Control system / SIS logic solver | C22: Positive displacement pump | D22: Casing | F22: Positive displacement pump | G22: STP – Fail to stop on demand | I22: 3.1 Control failure | K22: Calibration check
A23: Transformer | C23: Centrifugal compressor | D23: Impellers | F23: Positive displacement pump | G23: UST – Spurious stop | I23: 3.2 No signal / indication / alarm | K23: Shutdown inspection
A24: Switchgear / MCC / circuit breaker | C24: Centrifugal compressor | D24: Rotor / shaft | F24: Positive displacement pump | G24: BRD – Breakdown | I24: 3.3 Faulty signal / indication / alarm | K24: None – failure evident only on occurrence
A25: Variable speed drive / UPS | C25: Centrifugal compressor | D25: Journal and thrust bearings | F25: Positive displacement pump | G25: LOO – Low output (flow / head) | I25: 3.4 Out of adjustment / calibration drift | K25: None – hidden failure
A26: Hydraulic power unit / system | C26: Centrifugal compressor | D26: Dry gas / oil seals | F26: Positive displacement pump | G26: HIO – High output | I26: 3.5 Software / configuration failure
A27: Overhead crane / hoist (incl. ladle crane) | C27: Centrifugal compressor | D27: Lube oil system | F27: Positive displacement pump | G27: ELP – External leakage – process medium | I27: 3.6 Common cause / mode failure
A28: Water-cooled element (panel, roof, lance, tuyere, stave, mould) | C28: Centrifugal compressor | D28: Anti-surge valve and control | F28: Positive displacement pump | G28: ELU – External leakage – utility medium | I28: 4.0 Electrical failure – general
A29: Refractory lining (furnace, ladle, tundish, kiln) | C29: Centrifugal compressor | D29: Casing | F29: Positive displacement pump | G29: INL – Internal leakage / recirculation | I29: 4.1 Short circuiting
A30: Burner / combustion system | C30: Centrifugal compressor | D30: Coupling | F30: Positive displacement pump | G30: VIB – Vibration | I30: 4.2 Open circuit
A31: Cooling tower / closed cooling circuit | C31: Centrifugal compressor | D31: Inlet guide vanes | F31: Positive displacement pump | G31: NOI – Noise | I31: 4.3 No power / voltage
A32: Bag filter / dust collector | C32: Centrifugal compressor | D32: Protection instrumentation | F32: Positive displacement pump | G32: OHE – Overheating | I32: 4.4 Faulty power / voltage
A33: Ladle & ladle / transfer car | C33: Reciprocating compressor | D33: Cylinders and liners | F33: Positive displacement pump | G33: PDE – Parameter deviation | I33: 4.5 Earth / insulation fault
C34: Reciprocating compressor | D34: Pistons and rings | F34: Positive displacement pump | G34: STD – Structural deficiency | I34: 5.0 External influence – general
C35: Reciprocating compressor | D35: Valves | F35: Positive displacement pump | G35: PLU – Plugged / choked | I35: 5.1 Blockage / plugged
C36: Reciprocating compressor | D36: Rod packing | F36: Positive displacement pump | G36: OTH – Other | I36: 5.2 Contamination (process / lube oil / water)
C37: Reciprocating compressor | D37: Crankshaft and bearings | F37: Centrifugal compressor | G37: FTS – Fail to start on demand | I37: 5.3 Dust ingress
C38: Reciprocating compressor | D38: Crosshead | F38: Centrifugal compressor | G38: STP – Fail to stop on demand | I38: 5.4 Moisture / water ingress
C39: Reciprocating compressor | D39: Lube system | F39: Centrifugal compressor | G39: UST – Spurious stop | I39: 5.5 Heat / radiant heat / molten metal splash
C40: Reciprocating compressor | D40: Pulsation dampers | F40: Centrifugal compressor | G40: BRD – Breakdown | I40: 5.6 Mechanical impact / collision
C41: Reciprocating compressor | D41: Cooling system | F41: Centrifugal compressor | G41: LOO – Low output | I41: 6.0 Miscellaneous – general
...

Sheet Rating Scales
A1: RATING SCALES
A2: Typical process-plant scales – calibrate Occurrence with site failure history / reliability data and align Severity with the HAZOP risk matrix before the study.
B4: Severity (S) | C4: Rank | D4: Criteria
B5: 10 – Hazardous – without warning | C5: Hazardous – without warning | D5: Failure can cause fatality, major fire / explosion or major environmental release without warning
B6: 9 – Hazardous – with warning | C6: Hazardous – with warning | D6: Failure can cause fatality, serious injury or major release, with some warning
B7: 8 – Very high | C7: Very high | D7: Loss of primary function; plant / unit shutdown > 1 week or major equipment damage
B8: 7 – High | C8: High | D8: Loss of function; unit shutdown or major production loss of several days
B9: 6 – Moderate | C9: Moderate | D9: Partial loss of function; reduced throughput or quality; significant repair cost
B10: 5 – Low | C10: Low | D10: Reduced performance; repair without shutdown at notable cost; minor reportable incident
B11: 4 – Very low | C11: Very low | D11: Minor performance degradation noticed by operators; routine repair
B12: 3 – Minor | C12: Minor | D12: Minor effect on performance; repair at next opportunity
B13: 2 – Very minor | C13: Very minor | D13: Negligible effect; cosmetic or nuisance
B14: 1 – None | C14: None | D14: No discernible effect
B16: Occurrence (O) | C16: Rank | D16: Criteria
... B40: Action thresholds (editable) | C40: Value | D40: Meaning
B41: Severity threshold | C41: 9 | D41: Action required for any failure mode with S at or above this value
B42: RPN threshold | C42: 125 | D42: Action required for any failure mode with RPN at or above this value
B43: Action Priority | C43: H | D43: Action required for every failure mode with Action Priority H (and justify M items left without action)
B46: ACTION PRIORITY (AP) TABLE
B47: Based on the AIAG-VDA FMEA Handbook (2019) Action Priority logic. Editable – verify against your licensed copy / company standard.
B49: Severity band | C49: Occurrence band | D49: Detection band → | E49: D 7–10 | F49: D 5–6 | G49: D 2–4 | H49: D 1
B50: S 9–10 | C50: O 8–10 | E50: H | F50: H | G50: H | H50: H
B51: S 9–10 | C51: O 6–7 | E51: H | F51: H | G51: H | H51: H
B52: S 9–10 | C52: O 4–5 | E52: H | F52: H | G52: H | H52: M
B53: S 9–10 | C53: O 2–3 | E53: H | F53: M | G53: L | H53: L
B54: S 9–10 | C54: O 1 | E54: L | F54: L | G54: L | H54: L
B55: S 7–8 | C55: O 8–10 | E55: H | F55: H | G55: H | H55: H
B56: S 7–8 | C56: O 6–7 | E56: H | F56: H | G56: H | H56: M
B57: S 7–8 | C57: O 4–5 | E57: H | F57: M | G57: M | H57: M
B58: S 7–8 | C58: O 2–3 | E58: M | F58: M | G58: L | H58: L
B59: S 7–8 | C59: O 1 | E59: L | F59: L | G59: L | H59: L
B60: S 4–6 | C60: O 8–10 | E60: H | F60: H | G60: M | H60: M
B61: S 4–6 | C61: O 6–7 | E61: M | F61: M | G61: M | H61: L
... B74: S 1 | C74: O 1 | E74: L | F74: L | G74: L | H74: L
B76: Band lower limits (used by the AP look-up – keep in descending band order as in the table above)
B77: S band lower limits | E77: 9 | F77: 7 | G77: 4 | H77: 2 | I77: 1
B78: O band lower limits | E78: 8 | F78: 6 | G78: 4 | H78: 2 | I78: 1
B79: D band lower limits | E79: 7 | F79: 5 | G79: 2 | H79: 1

Sheet Summary
A1: FMECA SUMMARY
A2: Counts per system worksheet (calculated).
A4: Worksheet | B4: System | C4: Failure modes | D4: AP – High | E4: AP – Medium | F4: AP – Low | G4: Highest RPN | H4: Actions required | I4: Actions without owner | J4: AP High after action
A5: System 01 | B5: =IF('System 01'!$D$3="","",'System 01'!$D$3) | C5: =COUNTIF('System 01'!$F$14:$F$113,"?*") | D5: =COUNTIF('System 01'!$T$14:$T$113,"H") | E5: =COUNTIF('System 01'!$T$14:$T$113,"M") | F5: =COUNTIF('System 01'!$T$14:$T$113,"L") | G5: =IF(COUNT('System 01'!$S$14:$S$113)=0,"",MAX('System 01'!$S$14:$S$113)) | H5: =COUNTIF('System 01'!$U$14:$U$113,"Yes") | I5: =COUNTIFS('System 01'!$U$14:$U$113,"Yes",'System 01'!$X$14:$X$113,"") | J5: =COUNTIF('System 01'!$AD$14:$AD$113,"H")
A6: System 02 | B6: =IF('System 02'!$D$3="","",'System 02'!$D$3) | C6: =COUNTIF('System 02'!$F$14:$F$113,"?*") | D6: =COUNTIF('System 02'!$T$14:$T$113,"H") | E6: =COUNTIF('System 02'!$T$14:$T$113,"M") | F6: =COUNTIF('System 02'!$T$14:$T$113,"L") | G6: =IF(COUNT('System 02'!$S$14:$S$113)=0,"",MAX('System 02'!$S$14:$S$113)) | H6: =COUNTIF('System 02'!$U$14:$U$113,"Yes") | I6: =COUNTIFS('System 02'!$U$14:$U$113,"Yes",'System 02'!$X$14:$X$113,"") | J6: =COUNTIF('System 02'!$AD$14:$AD$113,"H")
A7: System 03 | B7: =IF('System 03'!$D$3="","",'System 03'!$D$3) | C7: =COUNTIF('System 03'!$F$14:$F$113,"?*") | D7: =COUNTIF('System 03'!$T$14:$T$113,"H") | E7: =COUNTIF('System 03'!$T$14:$T$113,"M") | F7: =COUNTIF('System 03'!$T$14:$T$113,"L") | G7: =IF(COUNT('System 03'!$S$14:$S$113)=0,"",MAX('System 03'!$S$14:$S$113)) | H7: =COUNTIF('System 03'!$U$14:$U$113,"Yes") | I7: =COUNTIFS('System 03'!$U$14:$U$113,"Yes",'System 03'!$X$14:$X$113,"") | J7: =COUNTIF('System 03'!$AD$14:$AD$113,"H")
A8: System 04 | B8: =IF('System 04'!$D$3="","",'System 04'!$D$3) | C8: =COUNTIF('System 04'!$F$14:$F$113,"?*") | D8: =COUNTIF('System 04'!$T$14:$T$113,"H") | E8: =COUNTIF('System 04'!$T$14:$T$113,"M") | F8: =COUNTIF('System 04'!$T$14:$T$113,"L") | G8: =IF(COUNT('System 04'!$S$14:$S$113)=0,"",MAX('System 04'!$S$14:$S$113)) | H8: =COUNTIF('System 04'!$U$14:$U$113,"Yes") | I8: =COUNTIFS('System 04'!$U$14:$U$113,"Yes",'System 04'!$X$14:$X$113,"") | J8: =COUNTIF('System 04'!$AD$14:$AD$113,"H")
A9: System 05 | B9: =IF('System 05'!$D$3="","",'System 05'!$D$3) | C9: =COUNTIF('System 05'!$F$14:$F$113,"?*") | D9: =COUNTIF('System 05'!$T$14:$T$113,"H") | E9: =COUNTIF('System 05'!$T$14:$T$113,"M") | F9: =COUNTIF('System 05'!$T$14:$T$113,"L") | G9: =IF(COUNT('System 05'!$S$14:$S$113)=0,"",MAX('System 05'!$S$14:$S$113)) | H9: =COUNTIF('System 05'!$U$14:$U$113,"Yes") | I9: =COUNTIFS('System 05'!$U$14:$U$113,"Yes",'System 05'!$X$14:$X$113,"") | J9: =COUNTIF('System 05'!$AD$14:$AD$113,"H")
A10: System 06 | B10: =IF('System 06'!$D$3="","",'System 06'!$D$3) | C10: =COUNTIF('System 06'!$F$14:$F$113,"?*") | D10: =COUNTIF('System 06'!$T$14:$T$113,"H") | E10: =COUNTIF('System 06'!$T$14:$T$113,"M") | F10: =COUNTIF('System 06'!$T$14:$T$113,"L") | G10: =IF(COUNT('System 06'!$S$14:$S$113)=0,"",MAX('System 06'!$S$14:$S$113)) | H10: =COUNTIF('System 06'!$U$14:$U$113,"Yes") | I10: =COUNTIFS('System 06'!$U$14:$U$113,"Yes",'System 06'!$X$14:$X$113,"") | J10: =COUNTIF('System 06'!$AD$14:$AD$113,"H")
A11: System 07 | B11: =IF('System 07'!$D$3="","",'System 07'!$D$3) | C11: =COUNTIF('System 07'!$F$14:$F$113,"?*") | D11: =COUNTIF('System 07'!$T$14:$T$113,"H") | E11: =COUNTIF('System 07'!$T$14:$T$113,"M") | F11: =COUNTIF('System 07'!$T$14:$T$113,"L") | G11: =IF(COUNT('System 07'!$S$14:$S$113)=0,"",MAX('System 07'!$S$14:$S$113)) | H11: =COUNTIF('System 07'!$U$14:$U$113,"Yes") | I11: =COUNTIFS('System 07'!$U$14:$U$113,"Yes",'System 07'!$X$14:$X$113,"") | J11: =COUNTIF('System 07'!$AD$14:$AD$113,"H")
A12: System 08 | B12: =IF('System 08'!$D$3="","",'System 08'!$D$3) | C12: =COUNTIF('System 08'!$F$14:$F$113,"?*") | D12: =COUNTIF('System 08'!$T$14:$T$113,"H") | E12: =COUNTIF('System 08'!$T$14:$T$113,"M") | F12: =COUNTIF('System 08'!$T$14:$T$113,"L") | G12: =IF(COUNT('System 08'!$S$14:$S$113)=0,"",MAX('System 08'!$S$14:$S$113)) | H12: =COUNTIF('System 08'!$U$14:$U$113,"Yes") | I12: =COUNTIFS('System 08'!$U$14:$U$113,"Yes",'System 08'!$X$14:$X$113,"") | J12: =COUNTIF('System 08'!$AD$14:$AD$113,"H")
A13: System 09 | B13: =IF('System 09'!$D$3="","",'System 09'!$D$3) | C13: =COUNTIF('System 09'!$F$14:$F$113,"?*") | D13: =COUNTIF('System 09'!$T$14:$T$113,"H") | E13: =COUNTIF('System 09'!$T$14:$T$113,"M") | F13: =COUNTIF('System 09'!$T$14:$T$113,"L") | G13: =IF(COUNT('System 09'!$S$14:$S$113)=0,"",MAX('System 09'!$S$14:$S$113)) | H13: =COUNTIF('System 09'!$U$14:$U$113,"Yes") | I13: =COUNTIFS('System 09'!$U$14:$U$113,"Yes",'System 09'!$X$14:$X$113,"") | J13: =COUNTIF('System 09'!$AD$14:$AD$113,"H")
A14: System 10 | B14: =IF('System 10'!$D$3="","",'System 10'!$D$3) | C14: =COUNTIF('System 10'!$F$14:$F$113,"?*") | D14: =COUNTIF('System 10'!$T$14:$T$113,"H") | E14: =COUNTIF('System 10'!$T$14:$T$113,"M") | F14: =COUNTIF('System 10'!$T$14:$T$113,"L") | G14: =IF(COUNT('System 10'!$S$14:$S$113)=0,"",MAX('System 10'!$S$14:$S$113)) | H14: =COUNTIF('System 10'!$U$14:$U$113,"Yes") | I14: =COUNTIFS('System 10'!$U$14:$U$113,"Yes",'System 10'!$X$14:$X$113,"") | J14: =COUNTIF('System 10'!$AD$14:$AD$113,"H")
A15: TOTAL | C15: =SUM(C5:C14) | D15: =SUM(D5:D14) | E15: =SUM(E5:E14) | F15: =SUM(F5:F14) | G15: =MAX(G5:G14) | H15: =SUM(H5:H14) | I15: =SUM(I5:I14) | J15: =SUM(J5:J14)
A17: Add rows here if you copy further System worksheets.

Sheet System 01
A1: FMECA WORKSHEET | F1: =Cover!B7
A3: Select system ▸ | D3: S01 – Gas receiving & metering station (GRMS) | K3: Session date | N3: Equipment items | O3: =IF($D$3="","",COUNTIFS(EqSys,$D$3,EqTag,"?*"))
A4: System title | D4: =IF($D$3="","",IFERROR(INDEX(Systems!$B$5:$B$34,MATCH($D$3,Systems!$C$5:$C$34,0))&"",""))
A5: Function / performance standard | D5: =IF($D$3="","",IFERROR(INDEX(Systems!$D$5:$D$34,MATCH($D$3,Systems!$C$5:$C$34,0))&"",""))
A6: Operating context | D6: =IF($D$3="","",IFERROR(INDEX(Systems!$E$5:$E$34,MATCH($D$3,Systems!$C$5:$C$34,0))&"",""))
A7: System boundaries | D7: =IF($D$3="","",IFERROR(INDEX(Systems!$F$5:$F$34,MATCH($D$3,Systems!$C$5:$C$34,0))&"",""))
A8: P&IDs / drawings | D8: =IF($D$3="","",IFERROR(INDEX(Systems!$G$5:$G$34,MATCH($D$3,Systems!$C$5:$C$34,0))&"",""))
A9: Related HAZOP node(s) | D9: =IF($D$3="","",IFERROR(INDEX(Systems!$H$5:$H$34,MATCH($D$3,Systems!$C$5:$C$34,0))&"",""))
A11: ONE ROW PER FAILURE MODE. Pick the equipment tag (tags of the selected system), component and failure mode; pick up to 3 causes (listed line by line in 'Failure causes / mechanisms'). Rate S, O, D – RPN, Action Priority and 'Action required?' are calculated. Rate again after the recommended action. Use the [–] button above the Cause columns to collapse them.
A12: ITEM / FAILURE MODE | G12: CAUSE PICK-LIST | J12: CAUSES & EFFECTS | N12: CRITICALITY – CURRENT | V12: RECOMMENDED ACTIONS | Z12: CRITICALITY – AFTER ACTION | AE12: LINKS
A13: Ref | B13: Equipment tag | C13: Equipment type (auto) | D13: Component / maintainable item | E13: Function of item | F13: Failure mode | G13: Cause 1 | H13: Cause 2 | I13: Cause 3 | J13: Failure causes / mechanisms | K13: Local effect | L13: System effect | M13: End effect (safety / environment / production) | N13: Severity (S) | O13: Current prevention controls | P13: Occurrence (O) | Q13: Current detection method | R13: Detection (D) | S13: RPN | T13: AP | U13: Action required? | V13: Recommended action | W13: Action / task type | X13: Action by | Y13: Due date | Z13: Severity (S) | AA13: Occurrence (O) | AB13: Detection (D) | AC13: RPN after | AD13: AP after | AE13: HAZOP ref. | AF13: Comments
A14: =IF(F14="","",LEFT($D$3,3)&"-"&TEXT(COUNTIF(F$14:F14,"?*"),"00")) | B14: ESDV-1001 | C14: =IF(B14="","",IFERROR(INDEX(EqTypeCol,MATCH(B14,EqTag,0)),"Tag not in register")) | D14: Actuator | E14: Close on ESD demand | F14: FTC – Fail to close on demand | G14: 1.6 Sticking / seizure | H14: 5.3 Dust ingress | I14: Inadequate inspection / maintenance interval | J14: =_xlfn.TEXTJOIN(CHAR(10),TRUE,IF(G14="","","• "&G14),IF(H14="","","• "&H14),IF(I14="","","• "&I14)) | K14: Inlet not isolated | L14: Release in the GRMS / PRS keeps being fed from the pipeline | M14: Prolonged jet fire / larger vapour cloud (ETA-GN-01 H2) | N14: 9 – Hazardous – with warning | O14: Annual full-stroke test | P14: 3 – Low | Q14: Proof test / function test | R14: 6 – Low | S14: =IF(OR(N14="",P14="",R14=""),"",(--TRIM(LEFT(N14,2)))*(--TRIM(LEFT(P14,2)))*(--TRIM(LEFT(R14,2)))) | T14: =IF(OR(N14="",P14="",R14=""),"",INDEX(APGrid,COUNTIF(APS,">"&(--TRIM(LEFT(N14,2))))*5+COUNTIF(APO,">"&(--TRIM(LEFT(P14,2))))+1,COUNTIF(APD,">"&(--TRIM(LEFT(R14,2))))+1)) | U14: =IF(S14="","",IF(OR((--TRIM(LEFT(N14,2)))>=SThr,S14>=RPNThr,T14="H"),"Yes","No")) | V14: Six-monthly partial-stroke test between annual full-stroke tests (R-001) | W14: Failure-finding / proof test | X14: Instrument engineer | Y14: 46477 | Z14: 9 – Hazardous – with warning | AA14: 3 – Low | AB14: 4 – Moderately high | AC14: =IF(OR(Z14="",AA14="",AB14=""),"",(--TRIM(LEFT(Z14,2)))*(--TRIM(LEFT(AA14,2)))*(--TRIM(LEFT(AB14,2)))) | AD14: =IF(OR(Z14="",AA14="",AB14=""),"",INDEX(APGrid,COUNTIF(APS,">"&(--TRIM(LEFT(Z14,2))))*5+COUNTIF(APO,">"&(--TRIM(LEFT(AA14,2))))+1,COUNTIF(APD,">"&(--TRIM(LEFT(AB14,2))))+1)) | AE14: HAZOP N01-05 | AF14: Fault tree FT-GN-02 event ESDV-1001 | AH14: =IFERROR(INDEX(EqTag,_xlfn.AGGREGATE(15,6,(ROW(EqTag)-4)/((EqSys=$D$3)*(EqTag<>"")),ROWS($AH$14:AH14))),"")
A15: =IF(F15="","",LEFT($D$3,3)&"-"&TEXT(COUNTIF(F$14:F15,"?*"),"00")) | B15: PR-1001 | C15: =IF(B15="","",IFERROR(INDEX(EqTypeCol,MATCH(B15,EqTag,0)),"Tag not in register")) | D15: Manway | E15: Contain pressure; open only when depressurised | F15: ELP – External leakage – process medium | G15: Incorrect operation / operator error | H15: 1.1 Leakage | J15: =_xlfn.TEXTJOIN(CHAR(10),TRUE,IF(G15="","","• "&G15),IF(H15="","","• "&H15),IF(I15="","","• "&I15)) | K15: Closure opened / leaking under pressure | L15: Gas release at the GRMS | M15: Injury to the operator; fire (BT-GN-01 T5) | N15: 10 – Hazardous – without warning | O15: Pigging procedure OP-GN-010 | P15: 3 – Low | Q15: None – failure evident only on occurrence | R15: 9 – Very remote | S15: =IF(OR(N15="",P15="",R15=""),"",(--TRIM(LEFT(N15,2)))*(--TRIM(LEFT(P15,2)))*(--TRIM(LEFT(R15,2)))) | T15: =IF(OR(N15="",P15="",R15=""),"",INDEX(APGrid,COUNTIF(APS,">"&(--TRIM(LEFT(N15,2))))*5+COUNTIF(APO,">"&(--TRIM(LEFT(P15,2))))+1,COUNTIF(APD,">"&(--TRIM(LEFT(R15,2))))+1)) | U15: =IF(S15="","",IF(OR((--TRIM(LEFT(N15,2)))>=SThr,S15>=RPNThr,T15="H"),"Yes","No")) | V15: Verify the pressure-warning / key-interlock device and train pigging crews (R-017) | W15: Redesign / modification (MOC) | X15: Mechanical engineer | Y15: 46477 | Z15: 10 – Hazardous – without warning | AA15: 2 – Remote | AB15: 4 – Moderately high | AC15: =IF(OR(Z15="",AA15="",AB15=""),"",(--TRIM(LEFT(Z15,2)))*(--TRIM(LEFT(AA15,2)))*(--TRIM(LEFT(AB15,2)))) | AD15: =IF(OR(Z15="",AA15="",AB15=""),"",INDEX(APGrid,COUNTIF(APS,">"&(--TRIM(LEFT(Z15,2))))*5+COUNTIF(APO,">"&(--TRIM(LEFT(AA15,2))))+1,COUNTIF(APD,">"&(--TRIM(LEFT(AB15,2))))+1)) | AE15: HAZOP N01-07 | AH15: =IFERROR(INDEX(EqTag,_xlfn.AGGREGATE(15,6,(ROW(EqTag)-4)/((EqSys=$D$3)*(EqTag<>"")),ROWS($AH$14:AH15))),"")
A16: =IF(F16="","",LEFT($D$3,3)&"-"&TEXT(COUNTIF(F$14:F16,"?*"),"00")) | B16: F-1002A | C16: =IF(B16="","",IFERROR(INDEX(EqTypeCol,MATCH(B16,EqTag,0)),"Tag not in register")) | D16: Internals | E16: Remove liquids and solids | F16: PLU – Plugged / fouled | G16: 5.1 Blockage / plugged | H16: 5.2 Contamination (process / lube oil / water) | J16: =_xlfn.TEXTJOIN(CHAR(10),TRUE,IF(G16="","","• "&G16),IF(H16="","","• "&H16),IF(I16="","","• "&I16)) | K16: High differential pressure | L16: Change-over to F-1002B; carry-over to regulators if not acted on | M16: Active regulator may stick open (FT-GN-01 initiating cause) | N16: 6 – Moderate | O16: Duty / standby; element change on dP | P16: 5 – Moderate | Q16: Performance monitoring (flow, ΔP, efficiency) | R16: 3 – High | S16: =IF(OR(N16="",P16="",R16=""),"",(--TRIM(LEFT(N16,2)))*(--TRIM(LEFT(P16,2)))*(--TRIM(LEFT(R16,2)))) | T16: =IF(OR(N16="",P16="",R16=""),"",INDEX(APGrid,COUNTIF(APS,">"&(--TRIM(LEFT(N16,2))))*5+COUNTIF(APO,">"&(--TRIM(LEFT(P16,2))))+1,COUNTIF(APD,">"&(--TRIM(LEFT(R16,2))))+1)) | U16: =IF(S16="","",IF(OR((--TRIM(LEFT(N16,2)))>=SThr,S16>=RPNThr,T16="H"),"Yes","No")) | AC16: =IF(OR(Z16="",AA16="",AB16=""),"",(--TRIM(LEFT(Z16,2)))*(--TRIM(LEFT(AA16,2)))*(--TRIM(LEFT(AB16,2)))) | AD16: =IF(OR(Z16="",AA16="",AB16=""),"",INDEX(APGrid,COUNTIF(APS,">"&(--TRIM(LEFT(Z16,2))))*5+COUNTIF(APO,">"&(--TRIM(LEFT(AA16,2))))+1,COUNTIF(APD,">"&(--TRIM(LEFT(AB16,2))))+1)) | AE16: HAZOP N01-03 | AH16: =IFERROR(INDEX(EqTag,_xlfn.AGGREGATE(15,6,(ROW(EqTag)-4)/((EqSys=$D$3)*(EqTag<>"")),ROWS($AH$14:AH16))),"")
A17: =IF(F17="","",LEFT($D$3,3)&"-"&TEXT(COUNTIF(F$14:F17,"?*"),"00")) | B17: FT-1003A | C17: =IF(B17="","",IFERROR(INDEX(EqTypeCol,MATCH(B17,EqTag,0)),"Tag not in register")) | D17: Transmitter electronics | E17: Measure custody flow | F17: AIR – Abnormal instrument reading | G17: 3.4 Out of adjustment / calibration drift | J17: =_xlfn.TEXTJOIN(CHAR(10),TRUE,IF(G17="","","• "&G17),IF(H17="","","• "&H17),IF(I17="","","• "&I17)) | K17: Meter error | L17: Custody-transfer dispute | M17: Commercial only | N17: 3 – Minor | O17: Annual verification | P17: 4 – Low | Q17: Calibration check | R17: 3 – High | S17: =IF(OR(N17="",P17="",R17=""),"",(--TRIM(LEFT(N17,2)))*(--TRIM(LEFT(P17,2)))*(--TRIM(LEFT(R17,2)))) | T17: =IF(OR(N17="",P17="",R17=""),"",INDEX(APGrid,COUNTIF(APS,">"&(--TRIM(LEFT(N17,2))))*5+COUNTIF(APO,">"&(--TRIM(LEFT(P17,2))))+1,COUNTIF(APD,">"&(--TRIM(LEFT(R17,2))))+1)) | U17: =IF(S17="","",IF(OR((--TRIM(LEFT(N17,2)))>=SThr,S17>=RPNThr,T17="H"),"Yes","No")) | AC17: =IF(OR(Z17="",AA17="",AB17=""),"",(--TRIM(LEFT(Z17,2)))*(--TRIM(LEFT(AA17,2)))*(--TRIM(LEFT(AB17,2)))) | AD17: =IF(OR(Z17="",AA17="",AB17=""),"",INDEX(APGrid,COUNTIF(APS,">"&(--TRIM(LEFT(Z17,2))))*5+COUNTIF(APO,">"&(--TRIM(LEFT(AA17,2))))+1,COUNTIF(APD,">"&(--TRIM(LEFT(AB17,2))))+1)) | AE17: HAZOP N01-01 | AH17: =IFERROR(INDEX(EqTag,_xlfn.AGGREGATE(15,6,(ROW(EqTag)-4)/((EqSys=$D$3)*(EqTag<>"")),ROWS($AH$14:AH17))),"")
A18: =IF(F18="","",LEFT($D$3,3)&"-"&TEXT(COUNTIF(F$14:F18,"?*"),"00")) | B18: PSV-1006A | C18: =IF(B18="","",IFERROR(INDEX(EqTypeCol,MATCH(B18,EqTag,0)),"Tag not in register")) | D18: Nozzle and disc | E18: Relieve fire / thermal overpressure | F18: FTO – Fail to open on demand | G18: 2.2 Corrosion (general / pitting / CUI) | H18: 5.1 Blockage / plugged | J18: =_xlfn.TEXTJOIN(CHAR(10),TRUE,IF(G18="","","• "&G18),IF(H18="","","• "&H18),IF(I18="","","• "&I18)) | K18: No relief | L18: Filter-separator overpressure in a fire | M18: Vessel rupture in a fire | N18: 8 – Very high | O18: Bench test every 4 years | P18: 2 – Remote | Q18: Proof test / function test | R18: 7 – Very low | S18: =IF(OR(N18="",P18="",R18=""),"",(--TRIM(LEFT(N18,2)))*(--TRIM(LEFT(P18,2)))*(--TRIM(LEFT(R18,2)))) | T18: =IF(OR(N18="",P18="",R18=""),"",INDEX(APGrid,COUNTIF(APS,">"&(--TRIM(LEFT(N18,2))))*5+COUNTIF(APO,">"&(--TRIM(LEFT(P18,2))))+1,COUNTIF(APD,">"&(--TRIM(LEFT(R18,2))))+1)) | U18: =IF(S18="","",IF(OR((--TRIM(LEFT(N18,2)))>=SThr,S18>=RPNThr,T18="H"),"Yes","No")) | V18: Reduce the bench-test interval to 2 years (fire-case relief only protection) | W18: Failure-finding / proof test | X18: Mechanical engineer | Y18: 46477 | Z18: 8 – Very high | AA18: 2 – Remote | AB18: 5 – Moderate | AC18: =IF(OR(Z18="",AA18="",AB18=""),"",(--TRIM(LEFT(Z18,2)))*(--TRIM(LEFT(AA18,2)))*(--TRIM(LEFT(AB18,2)))) | AD18: =IF(OR(Z18="",AA18="",AB18=""),"",INDEX(APGrid,COUNTIF(APS,">"&(--TRIM(LEFT(Z18,2))))*5+COUNTIF(APO,">"&(--TRIM(LEFT(AA18,2))))+1,COUNTIF(APD,">"&(--TRIM(LEFT(AB18,2))))+1)) | AE18: HAZOP N01-02 | AH18: =IFERROR(INDEX(EqTag,_xlfn.AGGREGATE(15,6,(ROW(EqTag)-4)/((EqSys=$D$3)*(EqTag<>"")),ROWS($AH$14:AH18))),"")
A19: =IF(F19="","",LEFT($D$3,3)&"-"&TEXT(COUNTIF(F$14:F19,"?*"),"00")) | C19: =IF(B19="","",IFERROR(INDEX(EqTypeCol,MATCH(B19,EqTag,0)),"Tag not in register")) | J19: =_xlfn.TEXTJOIN(CHAR(10),TRUE,IF(G19="","","• "&G19),IF(H19="","","• "&H19),IF(I19="","","• "&I19)) | S19: =IF(OR(N19="",P19="",R19=""),"",(--TRIM(LEFT(N19,2)))*(--TRIM(LEFT(P19,2)))*(--TRIM(LEFT(R19,2)))) | T19: =IF(OR(N19="",P19="",R19=""),"",INDEX(APGrid,COUNTIF(APS,">"&(--TRIM(LEFT(N19,2))))*5+COUNTIF(APO,">"&(--TRIM(LEFT(P19,2))))+1,COUNTIF(APD,">"&(--TRIM(LEFT(R19,2))))+1)) | U19: =IF(S19="","",IF(OR((--TRIM(LEFT(N19,2)))>=SThr,S19>=RPNThr,T19="H"),"Yes","No")) | AC19: =IF(OR(Z19="",AA19="",AB19=""),"",(--TRIM(LEFT(Z19,2)))*(--TRIM(LEFT(AA19,2)))*(--TRIM(LEFT(AB19,2)))) | AD19: =IF(OR(Z19="",AA19="",AB19=""),"",INDEX(APGrid,COUNTIF(APS,">"&(--TRIM(LEFT(Z19,2))))*5+COUNTIF(APO,">"&(--TRIM(LEFT(AA19,2))))+1,COUNTIF(APD,">"&(--TRIM(LEFT(AB19,2))))+1)) | AH19: =IFERROR(INDEX(EqTag,_xlfn.AGGREGATE(15,6,(ROW(EqTag)-4)/((EqSys=$D$3)*(EqTag<>"")),ROWS($AH$14:AH19))),"")
A20: =IF(F20="","",LEFT($D$3,3)&"-"&TEXT(COUNTIF(F$14:F20,"?*"),"00")) | C20: =IF(B20="","",IFERROR(INDEX(EqTypeCol,MATCH(B20,EqTag,0)),"Tag not in register")) | J20: =_xlfn.TEXTJOIN(CHAR(10),TRUE,IF(G20="","","• "&G20),IF(H20="","","• "&H20),IF(I20="","","• "&I20)) | S20: =IF(OR(N20="",P20="",R20=""),"",(--TRIM(LEFT(N20,2)))*(--TRIM(LEFT(P20,2)))*(--TRIM(LEFT(R20,2)))) | T20: =IF(OR(N20="",P20="",R20=""),"",INDEX(APGrid,COUNTIF(APS,">"&(--TRIM(LEFT(N20,2))))*5+COUNTIF(APO,">"&(--TRIM(LEFT(P20,2))))+1,COUNTIF(APD,">"&(--TRIM(LEFT(R20,2))))+1)) | U20: =IF(S20="","",IF(OR((--TRIM(LEFT(N20,2)))>=SThr,S20>=RPNThr,T20="H"),"Yes","No")) | AC20: =IF(OR(Z20="",AA20="",AB20=""),"",(--TRIM(LEFT(Z20,2)))*(--TRIM(LEFT(AA20,2)))*(--TRIM(LEFT(AB20,2)))) | AD20: =IF(OR(Z20="",AA20="",AB20=""),"",INDEX(APGrid,COUNTIF(APS,">"&(--TRIM(LEFT(Z20,2))))*5+COUNTIF(APO,">"&(--TRIM(LEFT(AA20,2))))+1,COUNTIF(APD,">"&(--TRIM(LEFT(AB20,2))))+1)) | AH20: =IFERROR(INDEX(EqTag,_xlfn.AGGREGATE(15,6,(ROW(EqTag)-4)/((EqSys=$D$3)*(EqTag<>"")),ROWS($AH$14:AH20))),"")
A21: =IF(F21="","",LEFT($D$3,3)&"-"&TEXT(COUNTIF(F$14:F21,"?*"),"00")) | C21: =IF(B21="","",IFERROR(INDEX(EqTypeCol,MATCH(B21,EqTag,0)),"Tag not in register")) | J21: =_xlfn.TEXTJOIN(CHAR(10),TRUE,IF(G21="","","• "&G21),IF(H21="","","• "&H21),IF(I21="","","• "&I21)) | S21: =IF(OR(N21="",P21="",R21=""),"",(--TRIM(LEFT(N21,2)))*(--TRIM(LEFT(P21,2)))*(--TRIM(LEFT(R21,2)))) | T21: =IF(OR(N21="",P21="",R21=""),"",INDEX(APGrid,COUNTIF(APS,">"&(--TRIM(LEFT(N21,2))))*5+COUNTIF(APO,">"&(--TRIM(LEFT(P21,2))))+1,COUNTIF(APD,">"&(--TRIM(LEFT(R21,2))))+1)) | U21: =IF(S21="","",IF(OR((--TRIM(LEFT(N21,2)))>=SThr,S21>=RPNThr,T21="H"),"Yes","No")) | AC21: =IF(OR(Z21="",AA21="",AB21=""),"",(--TRIM(LEFT(Z21,2)))*(--TRIM(LEFT(AA21,2)))*(--TRIM(LEFT(AB21,2)))) | AD21: =IF(OR(Z21="",AA21="",AB21=""),"",INDEX(APGrid,COUNTIF(APS,">"&(--TRIM(LEFT(Z21,2))))*5+COUNTIF(APO,">"&(--TRIM(LEFT(AA21,2))))+1,COUNTIF(APD,">"&(--TRIM(LEFT(AB21,2))))+1)) | AH21: =IFERROR(INDEX(EqTag,_xlfn.AGGREGATE(15,6,(ROW(EqTag)-4)/((EqSys=$D$3)*(EqTag<>"")),ROWS($AH$14:AH21))),"")
A22: =IF(F22="","",LEFT($D$3,3)&"-"&TEXT(COUNTIF(F$14:F22,"?*"),"00")) | C22: =IF(B22="","",IFERROR(INDEX(EqTypeCol,MATCH(B22,EqTag,0)),"Tag not in register")) | J22: =_xlfn.TEXTJOIN(CHAR(10),TRUE,IF(G22="","","• "&G22),IF(H22="","","• "&H22),IF(I22="","","• "&I22)) | S22: =IF(OR(N22="",P22="",R22=""),"",(--TRIM(LEFT(N22,2)))*(--TRIM(LEFT(P22,2)))*(--TRIM(LEFT(R22,2)))) | T22: =IF(OR(N22="",P22="",R22=""),"",INDEX(APGrid,COUNTIF(APS,">"&(--TRIM(LEFT(N22,2))))*5+COUNTIF(APO,">"&(--TRIM(LEFT(P22,2))))+1,COUNTIF(APD,">"&(--TRIM(LEFT(R22,2))))+1)) | U22: =IF(S22="","",IF(OR((--TRIM(LEFT(N22,2)))>=SThr,S22>=RPNThr,T22="H"),"Yes","No")) | AC22: =IF(OR(Z22="",AA22="",AB22=""),"",(--TRIM(LEFT(Z22,2)))*(--TRIM(LEFT(AA22,2)))*(--TRIM(LEFT(AB22,2)))) | AD22: =IF(OR(Z22="",AA22="",AB22=""),"",INDEX(APGrid,COUNTIF(APS,">"&(--TRIM(LEFT(Z22,2))))*5+COUNTIF(APO,">"&(--TRIM(LEFT(AA22,2))))+1,COUNTIF(APD,">"&(--TRIM(LEFT(AB22,2))))+1)) | AH22: =IFERROR(INDEX(EqTag,_xlfn.AGGREGATE(15,6,(ROW(EqTag)-4)/((EqSys=$D$3)*(EqTag<>"")),ROWS($AH$14:AH22))),"")
A23: =IF(F23="","",LEFT($D$3,3)&"-"&TEXT(COUNTIF(F$14:F23,"?*"),"00")) | C23: =IF(B23="","",IFERROR(INDEX(EqTypeCol,MATCH(B23,EqTag,0)),"Tag not in register")) | J23: =_xlfn.TEXTJOIN(CHAR(10),TRUE,IF(G23="","","• "&G23),IF(H23="","","• "&H23),IF(I23="","","• "&I23)) | S23: =IF(OR(N23="",P23="",R23=""),"",(--TRIM(LEFT(N23,2)))*(--TRIM(LEFT(P23,2)))*(--TRIM(LEFT(R23,2)))) | T23: =IF(OR(N23="",P23="",R23=""),"",INDEX(APGrid,COUNTIF(APS,">"&(--TRIM(LEFT(N23,2))))*5+COUNTIF(APO,">"&(--TRIM(LEFT(P23,2))))+1,COUNTIF(APD,">"&(--TRIM(LEFT(R23,2))))+1)) | U23: =IF(S23="","",IF(OR((--TRIM(LEFT(N23,2)))>=SThr,S23>=RPNThr,T23="H"),"Yes","No")) | AC23: =IF(OR(Z23="",AA23="",AB23=""),"",(--TRIM(LEFT(Z23,2)))*(--TRIM(LEFT(AA23,2)))*(--TRIM(LEFT(AB23,2)))) | AD23: =IF(OR(Z23="",AA23="",AB23=""),"",INDEX(APGrid,COUNTIF(APS,">"&(--TRIM(LEFT(Z23,2))))*5+COUNTIF(APO,">"&(--TRIM(LEFT(AA23,2))))+1,COUNTIF(APD,">"&(--TRIM(LEFT(AB23,2))))+1)) | AH23: =IFERROR(INDEX(EqTag,_xlfn.AGGREGATE(15,6,(ROW(EqTag)-4)/((EqSys=$D$3)*(EqTag<>"")),ROWS($AH$14:AH23))),"")
A24: =IF(F24="","",LEFT($D$3,3)&"-"&TEXT(COUNTIF(F$14:F24,"?*"),"00")) | C24: =IF(B24="","",IFERROR(INDEX(EqTypeCol,MATCH(B24,EqTag,0)),"Tag not in register")) | J24: =_xlfn.TEXTJOIN(CHAR(10),TRUE,IF(G24="","","• "&G24),IF(H24="","","• "&H24),IF(I24="","","• "&I24)) | S24: =IF(OR(N24="",P24="",R24=""),"",(--TRIM(LEFT(N24,2)))*(--TRIM(LEFT(P24,2)))*(--TRIM(LEFT(R24,2)))) | T24: =IF(OR(N24="",P24="",R24=""),"",INDEX(APGrid,COUNTIF(APS,">"&(--TRIM(LEFT(N24,2))))*5+COUNTIF(APO,">"&(--TRIM(LEFT(P24,2))))+1,COUNTIF(APD,">"&(--TRIM(LEFT(R24,2))))+1)) | U24: =IF(S24="","",IF(OR((--TRIM(LEFT(N24,2)))>=SThr,S24>=RPNThr,T24="H"),"Yes","No")) | AC24: =IF(OR(Z24="",AA24="",AB24=""),"",(--TRIM(LEFT(Z24,2)))*(--TRIM(LEFT(AA24,2)))*(--TRIM(LEFT(AB24,2)))) | AD24: =IF(OR(Z24="",AA24="",AB24=""),"",INDEX(APGrid,COUNTIF(APS,">"&(--TRIM(LEFT(Z24,2))))*5+COUNTIF(APO,">"&(--TRIM(LEFT(AA24,2))))+1,COUNTIF(APD,">"&(--TRIM(LEFT(AB24,2))))+1)) | AH24: =IFERROR(INDEX(EqTag,_xlfn.AGGREGATE(15,6,(ROW(EqTag)-4)/((EqSys=$D$3)*(EqTag<>"")),ROWS($AH$14:AH24))),"")
A25: =IF(F25="","",LEFT($D$3,3)&"-"&TEXT(COUNTIF(F$14:F25,"?*"),"00")) | C25: =IF(B25="","",IFERROR(INDEX(EqTypeCol,MATCH(B25,EqTag,0)),"Tag not in register")) | J25: =_xlfn.TEXTJOIN(CHAR(10),TRUE,IF(G25="","","• "&G25),IF(H25="","","• "&H25),IF(I25="","","• "&I25)) | S25: =IF(OR(N25="",P25="",R25=""),"",(--TRIM(LEFT(N25,2)))*(--TRIM(LEFT(P25,2)))*(--TRIM(LEFT(R25,2)))) | T25: =IF(OR(N25="",P25="",R25=""),"",INDEX(APGrid,COUNTIF(APS,">"&(--TRIM(LEFT(N25,2))))*5+COUNTIF(APO,">"&(--TRIM(LEFT(P25,2))))+1,COUNTIF(APD,">"&(--TRIM(LEFT(R25,2))))+1)) | U25: =IF(S25="","",IF(OR((--TRIM(LEFT(N25,2)))>=SThr,S25>=RPNThr,T25="H"),"Yes","No")) | AC25: =IF(OR(Z25="",AA25="",AB25=""),"",(--TRIM(LEFT(Z25,2)))*(--TRIM(LEFT(AA25,2)))*(--TRIM(LEFT(AB25,2)))) | AD25: =IF(OR(Z25="",AA25="",AB25=""),"",INDEX(APGrid,COUNTIF(APS,">"&(--TRIM(LEFT(Z25,2))))*5+COUNTIF(APO,">"&(--TRIM(LEFT(AA25,2))))+1,COUNTIF(APD,">"&(--TRIM(LEFT(AB25,2))))+1)) | AH25: =IFERROR(INDEX(EqTag,_xlfn.AGGREGATE(15,6,(ROW(EqTag)-4)/((EqSys=$D$3)*(EqTag<>"")),ROWS($AH$14:AH25))),"")
A26: =IF(F26="","",LEFT($D$3,3)&"-"&TEXT(COUNTIF(F$14:F26,"?*"),"00")) | C26: =IF(B26="","",IFERROR(INDEX(EqTypeCol,MATCH(B26,EqTag,0)),"Tag not in register")) | J26: =_xlfn.TEXTJOIN(CHAR(10),TRUE,IF(G26="","","• "&G26),IF(H26="","","• "&H26),IF(I26="","","• "&I26)) | S26: =IF(OR(N26="",P26="",R26=""),"",(--TRIM(LEFT(N26,2)))*(--TRIM(LEFT(P26,2)))*(--TRIM(LEFT(R26,2)))) | T26: =IF(OR(N26="",P26="",R26=""),"",INDEX(APGrid,COUNTIF(APS,">"&(--TRIM(LEFT(N26,2))))*5+COUNTIF(APO,">"&(--TRIM(LEFT(P26,2))))+1,COUNTIF(APD,">"&(--TRIM(LEFT(R26,2))))+1)) | U26: =IF(S26="","",IF(OR((--TRIM(LEFT(N26,2)))>=SThr,S26>=RPNThr,T26="H"),"Yes","No")) | AC26: =IF(OR(Z26="",AA26="",AB26=""),"",(--TRIM(LEFT(Z26,2)))*(--TRIM(LEFT(AA26,2)))*(--TRIM(LEFT(AB26,2)))) | AD26: =IF(OR(Z26="",AA26="",AB26=""),"",INDEX(APGrid,COUNTIF(APS,">"&(--TRIM(LEFT(Z26,2))))*5+COUNTIF(APO,">"&(--TRIM(LEFT(AA26,2))))+1,COUNTIF(APD,">"&(--TRIM(LEFT(AB26,2))))+1)) | AH26: =IFERROR(INDEX(EqTag,_xlfn.AGGREGATE(15,6,(ROW(EqTag)-4)/((EqSys=$D$3)*(EqTag<>"")),ROWS($AH$14:AH26))),"")
A27: =IF(F27="","",LEFT($D$3,3)&"-"&TEXT(COUNTIF(F$14:F27,"?*"),"00")) | C27: =IF(B27="","",IFERROR(INDEX(EqTypeCol,MATCH(B27,EqTag,0)),"Tag not in register")) | J27: =_xlfn.TEXTJOIN(CHAR(10),TRUE,IF(G27="","","• "&G27),IF(H27="","","• "&H27),IF(I27="","","• "&I27)) | S27: =IF(OR(N27="",P27="",R27=""),"",(--TRIM(LEFT(N27,2)))*(--TRIM(LEFT(P27,2)))*(--TRIM(LEFT(R27,2)))) | T27: =IF(OR(N27="",P27="",R27=""),"",INDEX(APGrid,COUNTIF(APS,">"&(--TRIM(LEFT(N27,2))))*5+COUNTIF(APO,">"&(--TRIM(LEFT(P27,2))))+1,COUNTIF(APD,">"&(--TRIM(LEFT(R27,2))))+1)) | U27: =IF(S27="","",IF(OR((--TRIM(LEFT(N27,2)))>=SThr,S27>=RPNThr,T27="H"),"Yes","No")) | AC27: =IF(OR(Z27="",AA27="",AB27=""),"",(--TRIM(LEFT(Z27,2)))*(--TRIM(LEFT(AA27,2)))*(--TRIM(LEFT(AB27,2)))) | AD27: =IF(OR(Z27="",AA27="",AB27=""),"",INDEX(APGrid,COUNTIF(APS,">"&(--TRIM(LEFT(Z27,2))))*5+COUNTIF(APO,">"&(--TRIM(LEFT(AA27,2))))+1,COUNTIF(APD,">"&(--TRIM(LEFT(AB27,2))))+1)) | AH27: =IFERROR(INDEX(EqTag,_xlfn.AGGREGATE(15,6,(ROW(EqTag)-4)/((EqSys=$D$3)*(EqTag<>"")),ROWS($AH$14:AH27))),"")
A28: =IF(F28="","",LEFT($D$3,3)&"-"&TEXT(COUNTIF(F$14:F28,"?*"),"00")) | C28: =IF(B28="","",IFERROR(INDEX(EqTypeCol,MATCH(B28,EqTag,0)),"Tag not in register")) | J28: =_xlfn.TEXTJOIN(CHAR(10),TRUE,IF(G28="","","• "&G28),IF(H28="","","• "&H28),IF(I28="","","• "&I28)) | S28: =IF(OR(N28="",P28="",R28=""),"",(--TRIM(LEFT(N28,2)))*(--TRIM(LEFT(P28,2)))*(--TRIM(LEFT(R28,2)))) | T28: =IF(OR(N28="",P28="",R28=""),"",INDEX(APGrid,COUNTIF(APS,">"&(--TRIM(LEFT(N28,2))))*5+COUNTIF(APO,">"&(--TRIM(LEFT(P28,2))))+1,COUNTIF(APD,">"&(--TRIM(LEFT(R28,2))))+1)) | U28: =IF(S28="","",IF(OR((--TRIM(LEFT(N28,2)))>=SThr,S28>=RPNThr,T28="H"),"Yes","No")) | AC28: =IF(OR(Z28="",AA28="",AB28=""),"",(--TRIM(LEFT(Z28,2)))*(--TRIM(LEFT(AA28,2)))*(--TRIM(LEFT(AB28,2)))) | AD28: =IF(OR(Z28="",AA28="",AB28=""),"",INDEX(APGrid,COUNTIF(APS,">"&(--TRIM(LEFT(Z28,2))))*5+COUNTIF(APO,">"&(--TRIM(LEFT(AA28,2))))+1,COUNTIF(APD,">"&(--TRIM(LEFT(AB28,2))))+1)) | AH28: =IFERROR(INDEX(EqTag,_xlfn.AGGREGATE(15,6,(ROW(EqTag)-4)/((EqSys=$D$3)*(EqTag<>"")),ROWS($AH$14:AH28))),"")
A29: =IF(F29="","",LEFT($D$3,3)&"-"&TEXT(COUNTIF(F$14:F29,"?*"),"00")) | C29: =IF(B29="","",IFERROR(INDEX(EqTypeCol,MATCH(B29,EqTag,0)),"Tag not in register")) | J29: =_xlfn.TEXTJOIN(CHAR(10),TRUE,IF(G29="","","• "&G29),IF(H29="","","• "&H29),IF(I29="","","• "&I29)) | S29: =IF(OR(N29="",P29="",R29=""),"",(--TRIM(LEFT(N29,2)))*(--TRIM(LEFT(P29,2)))*(--TRIM(LEFT(R29,2)))) | T29: =IF(OR(N29="",P29="",R29=""),"",INDEX(APGrid,COUNTIF(APS,">"&(--TRIM(LEFT(N29,2))))*5+COUNTIF(APO,">"&(--TRIM(LEFT(P29,2))))+1,COUNTIF(APD,">"&(--TRIM(LEFT(R29,2))))+1)) | U29: =IF(S29="","",IF(OR((--TRIM(LEFT(N29,2)))>=SThr,S29>=RPNThr,T29="H"),"Yes","No")) | AC29: =IF(OR(Z29="",AA29="",AB29=""),"",(--TRIM(LEFT(Z29,2)))*(--TRIM(LEFT(AA29,2)))*(--TRIM(LEFT(AB29,2)))) | AD29: =IF(OR(Z29="",AA29="",AB29=""),"",INDEX(APGrid,COUNTIF(APS,">"&(--TRIM(LEFT(Z29,2))))*5+COUNTIF(APO,">"&(--TRIM(LEFT(AA29,2))))+1,COUNTIF(APD,">"&(--TRIM(LEFT(AB29,2))))+1)) | AH29: =IFERROR(INDEX(EqTag,_xlfn.AGGREGATE(15,6,(ROW(EqTag)-4)/((EqSys=$D$3)*(EqTag<>"")),ROWS($AH$14:AH29))),"")
A30: =IF(F30="","",LEFT($D$3,3)&"-"&TEXT(COUNTIF(F$14:F30,"?*"),"00")) | C30: =IF(B30="","",IFERROR(INDEX(EqTypeCol,MATCH(B30,EqTag,0)),"Tag not in register")) | J30: =_xlfn.TEXTJOIN(CHAR(10),TRUE,IF(G30="","","• "&G30),IF(H30="","","• "&H30),IF(I30="","","• "&I30)) | S30: =IF(OR(N30="",P30="",R30=""),"",(--TRIM(LEFT(N30,2)))*(--TRIM(LEFT(P30,2)))*(--TRIM(LEFT(R30,2)))) | T30: =IF(OR(N30="",P30="",R30=""),"",INDEX(APGrid,COUNTIF(APS,">"&(--TRIM(LEFT(N30,2))))*5+COUNTIF(APO,">"&(--TRIM(LEFT(P30,2))))+1,COUNTIF(APD,">"&(--TRIM(LEFT(R30,2))))+1)) | U30: =IF(S30="","",IF(OR((--TRIM(LEFT(N30,2)))>=SThr,S30>=RPNThr,T30="H"),"Yes","No")) | AC30: =IF(OR(Z30="",AA30="",AB30=""),"",(--TRIM(LEFT(Z30,2)))*(--TRIM(LEFT(AA30,2)))*(--TRIM(LEFT(AB30,2)))) | AD30: =IF(OR(Z30="",AA30="",AB30=""),"",INDEX(APGrid,COUNTIF(APS,">"&(--TRIM(LEFT(Z30,2))))*5+COUNTIF(APO,">"&(--TRIM(LEFT(AA30,2))))+1,COUNTIF(APD,">"&(--TRIM(LEFT(AB30,2))))+1)) | AH30: =IFERROR(INDEX(EqTag,_xlfn.AGGREGATE(15,6,(ROW(EqTag)-4)/((EqSys=$D$3)*(EqTag<>"")),ROWS($AH$14:AH30))),"")
... A113: =IF(F113="","",LEFT($D$3,3)&"-"&TEXT(COUNTIF(F$14:F113,"?*"),"00")) | C113: =IF(B113="","",IFERROR(INDEX(EqTypeCol,MATCH(B113,EqTag,0)),"Tag not in register")) | J113: =_xlfn.TEXTJOIN(CHAR(10),TRUE,IF(G113="","","• "&G113),IF(H113="","","• "&H113),IF(I113="","","• "&I113)) | S113: =IF(OR(N113="",P113="",R113=""),"",(--TRIM(LEFT(N113,2)))*(--TRIM(LEFT(P113,2)))*(--TRIM(LEFT(R113,2)))) | T113: =IF(OR(N113="",P113="",R113=""),"",INDEX(APGrid,COUNTIF(APS,">"&(--TRIM(LEFT(N113,2))))*5+COUNTIF(APO,">"&(--TRIM(LEFT(P113,2))))+1,COUNTIF(APD,">"&(--TRIM(LEFT(R113,2))))+1)) | U113: =IF(S113="","",IF(OR((--TRIM(LEFT(N113,2)))>=SThr,S113>=RPNThr,T113="H"),"Yes","No")) | AC113: =IF(OR(Z113="",AA113="",AB113=""),"",(--TRIM(LEFT(Z113,2)))*(--TRIM(LEFT(AA113,2)))*(--TRIM(LEFT(AB113,2)))) | AD113: =IF(OR(Z113="",AA113="",AB113=""),"",INDEX(APGrid,COUNTIF(APS,">"&(--TRIM(LEFT(Z113,2))))*5+COUNTIF(APO,">"&(--TRIM(LEFT(AA113,2))))+1,COUNTIF(APD,">"&(--TRIM(LEFT(AB113,2))))+1)) | AH113: =IFERROR(INDEX(EqTag,_xlfn.AGGREGATE(15,6,(ROW(EqTag)-4)/((EqSys=$D$3)*(EqTag<>"")),ROWS($AH$14:AH113))),"")

Sheet System 02
A1: FMECA WORKSHEET | F1: =Cover!B7
A3: Select system ▸ | D3: S02 – Gas heaters H-1101A/B and pressure reduction station PRS-1 | K3: Session date | N3: Equipment items | O3: =IF($D$3="","",COUNTIFS(EqSys,$D$3,EqTag,"?*"))
A4: System title | D4: =IF($D$3="","",IFERROR(INDEX(Systems!$B$5:$B$34,MATCH($D$3,Systems!$C$5:$C$34,0))&"",""))
A5: Function / performance standard | D5: =IF($D$3="","",IFERROR(INDEX(Systems!$D$5:$D$34,MATCH($D$3,Systems!$C$5:$C$34,0))&"",""))
A6: Operating context | D6: =IF($D$3="","",IFERROR(INDEX(Systems!$E$5:$E$34,MATCH($D$3,Systems!$C$5:$C$34,0))&"",""))
A7: System boundaries | D7: =IF($D$3="","",IFERROR(INDEX(Systems!$F$5:$F$34,MATCH($D$3,Systems!$C$5:$C$34,0))&"",""))
A8: P&IDs / drawings | D8: =IF($D$3="","",IFERROR(INDEX(Systems!$G$5:$G$34,MATCH($D$3,Systems!$C$5:$C$34,0))&"",""))
A9: Related HAZOP node(s) | D9: =IF($D$3="","",IFERROR(INDEX(Systems!$H$5:$H$34,MATCH($D$3,Systems!$C$5:$C$34,0))&"",""))
A11: ONE ROW PER FAILURE MODE. Pick the equipment tag (tags of the selected system), component and failure mode; pick up to 3 causes (listed line by line in 'Failure causes / mechanisms'). Rate S, O, D – RPN, Action Priority and 'Action required?' are calculated. Rate again after the recommended action. Use the [–] button above the Cause columns to collapse them.
A12: ITEM / FAILURE MODE | G12: CAUSE PICK-LIST | J12: CAUSES & EFFECTS | N12: CRITICALITY – CURRENT | V12: RECOMMENDED ACTIONS | Z12: CRITICALITY – AFTER ACTION | AE12: LINKS
A13: Ref | B13: Equipment tag | C13: Equipment type (auto) | D13: Component / maintainable item | E13: Function of item | F13: Failure mode | G13: Cause 1 | H13: Cause 2 | I13: Cause 3 | J13: Failure causes / mechanisms | K13: Local effect | L13: System effect | M13: End effect (safety / environment / production) | N13: Severity (S) | O13: Current prevention controls | P13: Occurrence (O) | Q13: Current detection method | R13: Detection (D) | S13: RPN | T13: AP | U13: Action required? | V13: Recommended action | W13: Action / task type | X13: Action by | Y13: Due date | Z13: Severity (S) | AA13: Occurrence (O) | AB13: Detection (D) | AC13: RPN after | AD13: AP after | AE13: HAZOP ref. | AF13: Comments
A14: =IF(F14="","",LEFT($D$3,3)&"-"&TEXT(COUNTIF(F$14:F14,"?*"),"00")) | B14: PCV-1104A | C14: =IF(B14="","",IFERROR(INDEX(EqTypeCol,MATCH(B14,EqTag,0)),"Tag not in register")) | D14: Trim (plug / seat) | E14: Control PRS outlet at 7.0 barg | F14: FTC – Fail to close on demand | G14: 5.2 Contamination (process / lube oil / water) | H14: 5.4 Moisture / water ingress | I14: 1.6 Sticking / seizure | J14: =_xlfn.TEXTJOIN(CHAR(10),TRUE,IF(G14="","","• "&G14),IF(H14="","","• "&H14),IF(I14="","","• "&I14)) | K14: Active regulator fails open | L14: Monitor regulator must take over (demand on protection) | M14: If monitor and slam-shut also fail – MP network overpressure (HAZOP N02-02) | N14: 9 – Hazardous – with warning | O14: Pilot filter; heater keeps outlet ≥ 5 °C | P14: 5 – Moderate | Q14: Process alarm (DCS) | R14: 3 – High | S14: =IF(OR(N14="",P14="",R14=""),"",(--TRIM(LEFT(N14,2)))*(--TRIM(LEFT(P14,2)))*(--TRIM(LEFT(R14,2)))) | T14: =IF(OR(N14="",P14="",R14=""),"",INDEX(APGrid,COUNTIF(APS,">"&(--TRIM(LEFT(N14,2))))*5+COUNTIF(APO,">"&(--TRIM(LEFT(P14,2))))+1,COUNTIF(APD,">"&(--TRIM(LEFT(R14,2))))+1)) | U14: =IF(S14="","",IF(OR((--TRIM(LEFT(N14,2)))>=SThr,S14>=RPNThr,T14="H"),"Yes","No")) | V14: Pilot supply filter change and heater outlet temperature alarm (R-004) | W14: Time-based maintenance / overhaul | X14: Instrument engineer | Y14: 46477 | Z14: 9 – Hazardous – with warning | AA14: 4 – Low | AB14: 3 – High | AC14: =IF(OR(Z14="",AA14="",AB14=""),"",(--TRIM(LEFT(Z14,2)))*(--TRIM(LEFT(AA14,2)))*(--TRIM(LEFT(AB14,2)))) | AD14: =IF(OR(Z14="",AA14="",AB14=""),"",INDEX(APGrid,COUNTIF(APS,">"&(--TRIM(LEFT(Z14,2))))*5+COUNTIF(APO,">"&(--TRIM(LEFT(AA14,2))))+1,COUNTIF(APD,">"&(--TRIM(LEFT(AB14,2))))+1)) | AE14: HAZOP N02-02 | AF14: Initiating event in fault tree FT-GN-01 (BE-001) | AH14: =IFERROR(INDEX(EqTag,_xlfn.AGGREGATE(15,6,(ROW(EqTag)-4)/((EqSys=$D$3)*(EqTag<>"")),ROWS($AH$14:AH14))),"")
